Workbook
Name ACOInsight1: Inputs!$D$18:$D$19

Sheet Inputs
B1: Month Contract Starts | C1: 43101
B2: Contract Months | C2: 12
D3: Data Feed #1 | E3: Data Feed #2 | F3: Data Feed #3 | G3: Data Feed #4 | H3: Data Feed #5
B4: CCLF | D4: Y | L4: Y
B5: Collaborative Member | D5: N | L5: N
B6: Non-CMS Files | D6: N
B7: Initial Estimated Lives | D7: 50000
B8: Basic Datamart | D8: Y
B9: HCC Risk Scores | D9: Y
B10: HCG Benchmarks | D10: Y
B11: PAC/Grouping/Benchmarks | D11: Y
B12: Key Claims Metrics | D12: Y
B13: Waste Calculator | D13: Y
B14: Medical Conditions | D14: Y
B15: PRM Oppourtunity Prospective Scores | D15: N
B16: PRM Conditions to Consider | D16: N
B17: PRM Medicare ACO Analytics | D17: N
B18: ACO Insight - Basic | D18: N
B19: ACO Insight - Enhanced | D19: N
... B21: PRM Physician Risk and Credibility Adjusted Report | D21: N
C24: Additional Annual Cost | D24: 7250
D25: 90% to NY, 10% PRM for marginal increase
C26: Annual Additional NY | D26: =D24*0.9 -> 6525
C27: Annual Additional PRM | D27: =D24*0.1 -> 725

Sheet Outputs_External
D2: Data Feed #1 | E2: Data Feed #2 | F2: Data Feed #3 | G2: Data Feed #4 | H2: Data Feed #5
B3: One-Time Fees:
C4: Implementation | D4: =MAX(Calcs!D4, 0) -> 5000 | E4: =MAX(Calcs!E4, 0) -> 0 | F4: =MAX(Calcs!F4, 0) -> 0 | G4: =MAX(Calcs!G4, 0) -> 0 | H4: =MAX(Calcs!H4, 0) -> 0
B6: Annual Data Fees:
C7: Base Processing Fee | D7: =SUM(Calcs!D35, Calcs!D48) -> 18000 | E7: =SUM(Calcs!E35, Calcs!E48) -> 0 | F7: =SUM(Calcs!F35, Calcs!F48) -> 0 | G7: =SUM(Calcs!G35, Calcs!G48) -> 0 | H7: =SUM(Calcs!H35, Calcs!H48) -> 0
C8: Datamart Fee | D8: =SUM(Calcs!D36, Calcs!D49) -> 8100 | E8: =SUM(Calcs!E36, Calcs!E49) -> 0 | F8: =SUM(Calcs!F36, Calcs!F49) -> 0 | G8: =SUM(Calcs!G36, Calcs!G49) -> 0 | H8: =SUM(Calcs!H36, Calcs!H49) -> 0
C9: HCC Risk Scores | D9: =SUM(Calcs!D37, Calcs!D50) -> 1200 | E9: =SUM(Calcs!E37, Calcs!E50) -> 0 | F9: =SUM(Calcs!F37, Calcs!F50) -> 0 | G9: =SUM(Calcs!G37, Calcs!G50) -> 0 | H9: =SUM(Calcs!H37, Calcs!H50) -> 0
C10: HCG Benchmarks | D10: =SUM(Calcs!D38, Calcs!D51) -> 4800 | E10: =SUM(Calcs!E38, Calcs!E51) -> 0 | F10: =SUM(Calcs!F38, Calcs!F51) -> 0 | G10: =SUM(Calcs!G38, Calcs!G51) -> 0 | H10: =SUM(Calcs!H38, Calcs!H51) -> 0
C11: PAC/Grouping/Benchmarks | D11: =SUM(Calcs!D39, Calcs!D52) -> 2400 | E11: =SUM(Calcs!E39, Calcs!E52) -> 0 | F11: =SUM(Calcs!F39, Calcs!F52) -> 0 | G11: =SUM(Calcs!G39, Calcs!G52) -> 0 | H11: =SUM(Calcs!H39, Calcs!H52) -> 0
C12: Key Claims Metrics | D12: =SUM(Calcs!D40, Calcs!D53) -> 2400 | E12: =SUM(Calcs!E40, Calcs!E53) -> 0 | F12: =SUM(Calcs!F40, Calcs!F53) -> 0 | G12: =SUM(Calcs!G40, Calcs!G53) -> 0 | H12: =SUM(Calcs!H40, Calcs!H53) -> 0
C13: Waste Calculator | D13: =SUM(Calcs!D41, Calcs!D54) -> 7200 | E13: =SUM(Calcs!E41, Calcs!E54) -> 0 | F13: =SUM(Calcs!F41, Calcs!F54) -> 0 | G13: =SUM(Calcs!G41, Calcs!G54) -> 0 | H13: =SUM(Calcs!H41, Calcs!H54) -> 0
C14: Medical Conditions | D14: =SUM(Calcs!D42, Calcs!D55) -> 4800 | E14: =SUM(Calcs!E42, Calcs!E55) -> 0 | F14: =SUM(Calcs!F42, Calcs!F55) -> 0 | G14: =SUM(Calcs!G42, Calcs!G55) -> 0 | H14: =SUM(Calcs!H42, Calcs!H55) -> 0
C15: PRM Oppourtunity Prospective Scores | D15: =SUM(Calcs!D43, Calcs!D56) -> 0 | E15: =SUM(Calcs!E43, Calcs!E56) -> 0 | F15: =SUM(Calcs!F43, Calcs!F56) -> 0 | G15: =SUM(Calcs!G43, Calcs!G56) -> 0 | H15: =SUM(Calcs!H43, Calcs!H56) -> 0
C16: PRM Conditions to Consider | D16: =SUM(Calcs!D44, Calcs!D57) -> 0 | E16: =SUM(Calcs!E44, Calcs!E57) -> 0 | F16: =SUM(Calcs!F44, Calcs!F57) -> 0 | G16: =SUM(Calcs!G44, Calcs!G57) -> 0 | H16: =SUM(Calcs!H44, Calcs!H57) -> 0
C17: PRM Medicare ACO Analytics (CCLF Only) | D17: =SUM(Calcs!D45, Calcs!D58) -> 0 | E17: =SUM(Calcs!E45, Calcs!E58) -> 0 | F17: =SUM(Calcs!F45, Calcs!F58) -> 0 | G17: =SUM(Calcs!G45, Calcs!G58) -> 0 | H17: =SUM(Calcs!H45, Calcs!H58) -> 0
B19: Annual Product Fees
C20: ACO Insight - Basic | D20: =SUM(Calcs!D61, Calcs!D67) -> 0 | E20: =SUM(Calcs!E61, Calcs!E67) -> 0 | F20: =SUM(Calcs!F61, Calcs!F67) -> 0 | G20: =SUM(Calcs!G61, Calcs!G67) -> 0 | H20: =SUM(Calcs!H61, Calcs!H67) -> 0
C21: ACO Insight - Enhanced | D21: =SUM(Calcs!D62, Calcs!D68) -> 0 | E21: =SUM(Calcs!E62, Calcs!E68) -> 0 | F21: =SUM(Calcs!F62, Calcs!F68) -> 0 | G21: =SUM(Calcs!G62, Calcs!G68) -> 0 | H21: =SUM(Calcs!H62, Calcs!H68) -> 0
C22: PRM Care Coordinator Report | D22: =SUM(Calcs!D63, Calcs!D69) -> 0 | E22: =SUM(Calcs!E63, Calcs!E69) -> 0 | F22: =SUM(Calcs!F63, Calcs!F69) -> 0 | G22: =SUM(Calcs!G63, Calcs!G69) -> 0 | H22: =SUM(Calcs!H63, Calcs!H69) -> 0
C23: PRM Physician Risk and Credibility Adjusted Report | D23: =SUM(Calcs!D64, Calcs!D70) -> 0 | E23: =SUM(Calcs!E64, Calcs!E70) -> 0 | F23: =SUM(Calcs!F64, Calcs!F70) -> 0 | G23: =SUM(Calcs!G64, Calcs!G70) -> 0 | H23: =SUM(Calcs!H64, Calcs!H70) -> 0
B25: Discounts
C26: Product Discounts | D26: =SUM(Calcs!D85:D86) -> 0 | E26: =SUM(Calcs!E85:E86) -> 0 | F26: =SUM(Calcs!F85:F86) -> 0 | G26: =SUM(Calcs!G85:G86) -> 0 | H26: =SUM(Calcs!H85:H86) -> 0
C27: Datafeed Discounts | D27: =Calcs!D90 -> 0 | E27: =Calcs!E90 -> 0 | F27: =Calcs!F90 -> 0 | G27: =Calcs!G90 -> 0 | H27: =Calcs!H90 -> 0
B29: Annual Total | D29: =SUM(D7:D17, D20:D23, D26:D27) -> 48900 | E29: =SUM(E7:E17, E20:E23, E26:E27) -> 0 | F29: =SUM(F7:F17, F20:F23, F26:F27) -> 0 | G29: =SUM(G7:G17, G20:G23, G26:G27) -> 0 | H29: =SUM(H7:H17, H20:H23, H26:H27) -> 0
B31: Price inflation multiplier
C32: =INDEX(Outputs_Timeline!$D$3:$D$94,MATCH(Inputs!$C$1,Outputs_Timeline!$B$3:$B$94,0),1) -> 1
B34: Prorated Total with Implementation | D34: =(D29/12*Inputs!$C$2+D4)*$C$32 -> 53900 | E34: =(E29/12*Inputs!$C$2+E4)*$C$32 -> 0 | F34: =(F29/12*Inputs!$C$2+F4)*$C$32 -> 0 | G34: =(G29/12*Inputs!$C$2+G4)*$C$32 -> 0 | H34: =(H29/12*Inputs!$C$2+H4)*$C$32 -> 0
B37: Total across entire contract duration
C38: =SUM(Outputs_Timeline!S:S) -> 61150
C39: =SUM(D34:H34) -> 53900

Sheet Outputs_Internal
F1: Revenue Split Percentages
D2: Totals | F2: New York | G2: PRM | H2: MI Royalties | I2: Other Royalties | K2: New York | L2: PRM | M2: MI Royalties | N2: Other Royalties
B3: One-Time Fees:
C4: Implementation (CCLF) | D4: =SUMIF(Inputs!$D$4:$H$4, "Y", Outputs_External!D4:'Outputs_External'!H4) -> 5000 | F4: 0.5 | G4: 0.5 | H4: =1-SUM(F4:G4) -> 0 | I4: 0 | K4: =F4*$D4 -> 2500 | L4: =G4*$D4 -> 2500 | M4: =H4*$D4 -> 0 | N4: =I4*$D4 -> 0
C5: Implementation (non-CCLF) | D5: =SUMIF(Inputs!$D$4:$H$4, "N", Outputs_External!D4:'Outputs_External'!H4) -> 0 | F5: 0.1 | G5: 0.9 | H5: =1-SUM(F5:G5) -> 0 | I5: 0 | K5: =F5*$D5 -> 0 | L5: =G5*$D5 -> 0 | M5: =H5*$D5 -> 0 | N5: =I5*$D5 -> 0
B7: Annual Base Data Fees (with implicit forces):
C8: Base Processing Fee | D8: =SUM(Calcs!D9:H9) -> 18000 | F8: 0.4 | G8: 0.6 | H8: =1-SUM(F8:G8) -> 0 | I8: 0 | K8: =F8*$D8 -> 7200 | L8: =G8*$D8 -> 10800 | M8: =H8*$D8 -> 0 | N8: =I8*$D8 -> 0
C9: Datamart Fee | D9: =SUM(Calcs!D10:H10) -> 8100 | F9: 0.2 | G9: 0.8 | H9: =1-SUM(F9:G9) -> 0 | I9: 0 | K9: =F9*$D9 -> 1620 | L9: =G9*$D9 -> 6480 | M9: =H9*$D9 -> 0 | N9: =I9*$D9 -> 0
C10: HCC Risk Scores | D10: =SUM(Calcs!D11:H11) -> 1200 | F10: 0.1 | G10: 0.9 | H10: =1-SUM(F10:G10) -> 0 | I10: 0 | K10: =F10*$D10 -> 120 | L10: =G10*$D10 -> 1080 | M10: =H10*$D10 -> 0 | N10: =I10*$D10 -> 0
C11: HCG Benchmarks | D11: =SUM(Calcs!D12:H12) -> 4800 | F11: 0.45 | G11: 0.45 | H11: 0 | I11: 0.1 | K11: =F11*$D11 -> 2160 | L11: =G11*$D11 -> 2160 | M11: =H11*$D11 -> 0 | N11: =I11*$D11 -> 480
C12: PAC/Grouping/Benchmarks | D12: =SUM(Calcs!D13:H13) -> 2400 | F12: 0.9 | G12: 0.1 | H12: =1-SUM(F12:G12) -> 0 | I12: 0 | K12: =F12*$D12 -> 2160 | L12: =G12*$D12 -> 240 | M12: =H12*$D12 -> 0 | N12: =I12*$D12 -> 0
C13: Key Claims Metrics | D13: =SUM(Calcs!D14:H14) -> 2400 | F13: 0.1 | G13: 0.9 | H13: =1-SUM(F13:G13) -> 0 | I13: 0 | K13: =F13*$D13 -> 240 | L13: =G13*$D13 -> 2160 | M13: =H13*$D13 -> 0 | N13: =I13*$D13 -> 0
C14: Waste Calculator | D14: =SUM(Calcs!D15:H15) -> 7200 | F14: 0.1 | G14: 0.1 | H14: 0.8 | I14: 0 | K14: =F14*$D14 -> 720 | L14: =G14*$D14 -> 720 | M14: =H14*$D14 -> 5760 | N14: =I14*$D14 -> 0
C15: Medical Conditions | D15: =SUM(Calcs!D16:H16) -> 4800 | F15: 0.6 | G15: 0.4 | H15: =1-SUM(F15:G15) -> 0 | I15: 0 | K15: =F15*$D15 -> 2880 | L15: =G15*$D15 -> 1920 | M15: =H15*$D15 -> 0 | N15: =I15*$D15 -> 0
C16: PRM Oppourtunity Prospective Scores | D16: =SUM(Calcs!D17:H17) -> 0 | F16: 0.1 | G16: 0.9 | H16: =1-SUM(F16:G16) -> 0 | I16: 0 | K16: =F16*$D16 -> 0 | L16: =G16*$D16 -> 0 | M16: =H16*$D16 -> 0 | N16: =I16*$D16 -> 0
C17: PRM Conditions to Consider | D17: =SUM(Calcs!D18:H18) -> 0 | F17: 0.1 | G17: 0.9 | H17: =1-SUM(F17:G17) -> 0 | I17: 0 | K17: =F17*$D17 -> 0 | L17: =G17*$D17 -> 0 | M17: =H17*$D17 -> 0 | N17: =I17*$D17 -> 0
C18: PRM Medicare ACO Analytics (CCLF Only) | D18: =SUM(Calcs!D19:H19) -> 0 | F18: 0.1 | G18: 0.9 | H18: =1-SUM(F18:G18) -> 0 | I18: 0 | K18: =F18*$D18 -> 0 | L18: =G18*$D18 -> 0 | M18: =H18*$D18 -> 0 | N18: =I18*$D18 -> 0
G20: PRM Increase on PMPM Add-on fees: | H20: 0.1
B22: Annual PMPM Add-on Data Fees (with implicit forces):
C23: Base Processing Fee | D23: =SUM(Calcs!D22:H22) -> 0 | F23: =(1-G23)*F8/SUM(F8,H8) -> 0.3 | G23: =MIN(1,G8+$H$20) -> 0.7 | H23: =IF(H8=0, 0,(1-G23)*H8/SUM(F8,H8)) -> 0 | I23: =IF(I8=0, 0,(1-G23)*I8/SUM(F8,I8)) -> 0 | K23: =F23*$D23 -> 0 | L23: =G23*$D23 -> 0 | M23: =H23*$D23 -> 0 | N23: =I23*$D23 -> 0
C24: Datamart Fee | D24: =SUM(Calcs!D23:H23) -> 0 | F24: =(1-G24)*F9/SUM(F9,H9) -> 0.1 | G24: =MIN(1,G9+$H$20) -> 0.9 | H24: =IF(H9=0, 0,(1-G24)*H9/SUM(F9,H9)) -> 0 | I24: =IF(I9=0, 0,(1-G24)*I9/SUM(F9,I9)) -> 0 | K24: =F24*$D24 -> 0 | L24: =G24*$D24 -> 0 | M24: =H24*$D24 -> 0 | N24: =I24*$D24 -> 0
C25: HCC Risk Scores | D25: =SUM(Calcs!D24:H24) -> 0 | F25: =(1-G25)*F10/SUM(F10,H10) -> 0 | G25: =MIN(1,G10+$H$20) -> 1 | H25: =IF(H10=0, 0,(1-G25)*H10/SUM(F10,H10)) -> 0 | I25: =IF(I10=0, 0,(1-G25)*I10/SUM(F10,I10)) -> 0 | K25: =F25*$D25 -> 0 | L25: =G25*$D25 -> 0 | M25: =H25*$D25 -> 0 | N25: =I25*$D25 -> 0
C26: HCG Benchmarks | D26: =SUM(Calcs!D25:H25) -> 0 | F26: =(1-G26)*F11/SUM(F11,H11, I11) -> 0.36818182 | G26: =MIN(1,G11+$H$20) -> 0.55 | H26: =IF(H11=0, 0,(1-G26)*H11/SUM(F11,H11)) -> 0 | I26: =IF(I11=0, 0,(1-G26)*I11/SUM(F11,I11)) -> 0.081818182 | K26: =F26*$D26 -> 0 | L26: =G26*$D26 -> 0 | M26: =H26*$D26 -> 0 | N26: =I26*$D26 -> 0
C27: PAC/Grouping/Benchmarks | D27: =SUM(Calcs!D26:H26) -> 0 | F27: =(1-G27)*F12/SUM(F12,H12) -> 0.8 | G27: =MIN(1,G12+$H$20) -> 0.2 | H27: =IF(H12=0, 0,(1-G27)*H12/SUM(F12,H12)) -> 0 | I27: =IF(I12=0, 0,(1-G27)*I12/SUM(F12,I12)) -> 0 | K27: =F27*$D27 -> 0 | L27: =G27*$D27 -> 0 | M27: =H27*$D27 -> 0 | N27: =I27*$D27 -> 0
C28: Key Claims Metrics | D28: =SUM(Calcs!D27:H27) -> 0 | F28: =(1-G28)*F13/SUM(F13,H13) -> 0 | G28: =MIN(1,G13+$H$20) -> 1 | H28: =IF(H13=0, 0,(1-G28)*H13/SUM(F13,H13)) -> 0 | I28: =IF(I13=0, 0,(1-G28)*I13/SUM(F13,I13)) -> 0 | K28: =F28*$D28 -> 0 | L28: =G28*$D28 -> 0 | M28: =H28*$D28 -> 0 | N28: =I28*$D28 -> 0
C29: Waste Calculator | D29: =SUM(Calcs!D28:H28) -> 0 | F29: =(1-G29)*F14/SUM(F14,H14) -> 0.088888889 | G29: =MIN(1,G14+$H$20) -> 0.2 | H29: =IF(H14=0, 0,(1-G29)*H14/SUM(F14,H14)) -> 0.71111111 | I29: =IF(I14=0, 0,(1-G29)*I14/SUM(F14,I14)) -> 0 | K29: =F29*$D29 -> 0 | L29: =G29*$D29 -> 0 | M29: =H29*$D29 -> 0 | N29: =I29*$D29 -> 0
C30: Medical Conditions | D30: =SUM(Calcs!D29:H29) -> 0 | F30: =(1-G30)*F15/SUM(F15,H15) -> 0.5 | G30: =MIN(1,G15+$H$20) -> 0.5 | H30: =IF(H15=0, 0,(1-G30)*H15/SUM(F15,H15)) -> 0 | I30: =IF(I15=0, 0,(1-G30)*I15/SUM(F15,I15)) -> 0 | K30: =F30*$D30 -> 0 | L30: =G30*$D30 -> 0 | M30: =H30*$D30 -> 0 | N30: =I30*$D30 -> 0
C31: PRM Oppourtunity Prospective Scores | D31: =SUM(Calcs!D30:H30) -> 0 | F31: =(1-G31)*F16/SUM(F16,H16) -> 0 | G31: =MIN(1,G16+$H$20) -> 1 | H31: =IF(H16=0, 0,(1-G31)*H16/SUM(F16,H16)) -> 0 | I31: =IF(I16=0, 0,(1-G31)*I16/SUM(F16,I16)) -> 0 | K31: =F31*$D31 -> 0 | L31: =G31*$D31 -> 0 | M31: =H31*$D31 -> 0 | N31: =I31*$D31 -> 0
C32: PRM Conditions to Consider | D32: =SUM(Calcs!D31:H31) -> 0 | F32: =(1-G32)*F17/SUM(F17,H17) -> 0 | G32: =MIN(1,G17+$H$20) -> 1 | H32: =IF(H17=0, 0,(1-G32)*H17/SUM(F17,H17)) -> 0 | I32: =IF(I17=0, 0,(1-G32)*I17/SUM(F17,I17)) -> 0 | K32: =F32*$D32 -> 0 | L32: =G32*$D32 -> 0 | M32: =H32*$D32 -> 0 | N32: =I32*$D32 -> 0
C33: PRM Medicare ACO Analytics (CCLF Only) | D33: =SUM(Calcs!D32:H32) -> 0 | F33: =(1-G33)*F18/SUM(F18,H18) -> 0 | G33: =MIN(1,G18+$H$20) -> 1 | H33: =IF(H18=0, 0,(1-G33)*H18/SUM(F18,H18)) -> 0 | I33: =IF(I18=0, 0,(1-G33)*I18/SUM(F18,I18)) -> 0 | K33: =F33*$D33 -> 0 | L33: =G33*$D33 -> 0 | M33: =H33*$D33 -> 0 | N33: =I33*$D33 -> 0
B35: Annual Base Product Fees (Marginal over data fees)
C36: ACO Insight - Basic | D36: =SUM(Calcs!D73:H73) -> 0 | F36: 0.9 | G36: 0.1 | H36: =1-SUM(F36:G36) -> 0 | I36: 0 | K36: =F36*$D36 -> 0 | L36: =G36*$D36 -> 0 | M36: =H36*$D36 -> 0 | N36: =I36*$D36 -> 0
C37: ACO Insight - Enhanced | D37: =SUM(Calcs!D74:H74) -> 0 | F37: 0.9 | G37: 0.1 | H37: =1-SUM(F37:G37) -> 0 | I37: 0 | K37: =F37*$D37 -> 0 | L37: =G37*$D37 -> 0 | M37: =H37*$D37 -> 0 | N37: =I37*$D37 -> 0
C38: PRM Care Coordinator Report | D38: =SUM(Calcs!D75:H75) -> 0 | F38: 0.1 | G38: 0.9 | H38: =1-SUM(F38:G38) -> 0 | I38: 0 | K38: =F38*$D38 -> 0 | L38: =G38*$D38 -> 0 | M38: =H38*$D38 -> 0 | N38: =I38*$D38 -> 0
C39: PRM Physician Risk and Credibility Adjusted Report | D39: =SUM(Calcs!D76:H76) -> 0 | F39: 0.1 | G39: 0.9 | H39: =1-SUM(F39:G39) -> 0 | I39: 0 | K39: =F39*$D39 -> 0 | L39: =G39*$D39 -> 0 | M39: =H39*$D39 -> 0 | N39: =I39*$D39 -> 0
B41: Annual PMPM Add-on Product Fees (Marginal over data fees)
C42: ACO Insight - Basic | D42: =SUM(Calcs!D79:H79) -> 0 | F42: =IFERROR((1-G42)*F36/SUM(F36,H36),0) -> 0.8 | G42: =MIN(1,G36+$H$20) -> 0.2 | H42: =IFERROR((1-G42)*H36/SUM(F36,H36),0) -> 0 | I42: 0 | K42: =F42*$D42 -> 0 | L42: =G42*$D42 -> 0 | M42: =H42*$D42 -> 0 | N42: =I42*$D42 -> 0
C43: ACO Insight - Enhanced | D43: =SUM(Calcs!D80:H80) -> 0 | F43: =IFERROR((1-G43)*F37/SUM(F37,H37),0) -> 0.8 | G43: =MIN(1,G37+$H$20) -> 0.2 | H43: =IFERROR((1-G43)*H37/SUM(F37,H37),0) -> 0 | I43: 0 | K43: =F43*$D43 -> 0 | L43: =G43*$D43 -> 0 | M43: =H43*$D43 -> 0 | N43: =I43*$D43 -> 0
C44: PRM Care Coordinator Report | D44: =SUM(Calcs!D81:H81) -> 0 | F44: =IFERROR((1-G44)*F38/SUM(F38,H38),0) -> 0 | G44: =MIN(1,G38+$H$20) -> 1 | H44: =IFERROR((1-G44)*H38/SUM(F38,H38),0) -> 0 | I44: 0 | K44: =F44*$D44 -> 0 | L44: =G44*$D44 -> 0 | M44: =H44*$D44 -> 0 | N44: =I44*$D44 -> 0
C45: PRM Physician Risk and Credibility Adjusted Report | D45: =SUM(Calcs!D82:H82) -> 0 | F45: =IFERROR((1-G45)*F39/SUM(F39,H39),0) -> 0 | G45: =MIN(1,G39+$H$20) -> 1 | H45: =IFERROR((1-G45)*H39/SUM(F39,H39),0) -> 0 | I45: 0 | K45: =F45*$D45 -> 0 | L45: =G45*$D45 -> 0 | M45: =H45*$D45 -> 0 | N45: =I45*$D45 -> 0
...

Sheet Outputs_Timeline
F1: =COUNTIF(F3:F94,">0") -> 12 | H1: Implementation Fee | M1: Monthly Fees | S1: Quarterly Invoices
B2: Month | D2: Price Inflation | E2: Price Freeze | F2: Price Multiplier | H2: Total | I2: NY | J2: PRM | K2: MI | M2: Total | N2: NY | O2: PRM | P2: MI Royalties | Q2: Other Royalties | S2: Total | T2: NY | U2: PRM | V2: MI Royalties | W2: Other Royalties
B3: 42917 | D3: =1 -> 1 | E3: =IF(B3=Inputs!$C$1,D3,1) -> 1 | F3: =IF(AND(B3>=Inputs!$C$1,B3<EDATE(Inputs!$C$1,Inputs!$C$2)),E3,0) -> 0 | H3: =IF($B3=Inputs!$C$1,SUM(Outputs_Internal!$D$4, Outputs_Internal!$D$5),0)*$D3 -> 0 | I3: =IF($B3=Inputs!$C$1,SUM(Outputs_Internal!K$4, Outputs_Internal!K$5),0)*$D3 -> 0 | J3: =IF($B3=Inputs!$C$1,SUM(Outputs_Internal!L$4, Outputs_Internal!L$5),0)*$D3 -> 0 | K3: =IF($B3=Inputs!$C$1,SUM(Outputs_Internal!M$4, Outputs_Internal!$M$5),0)*$D3 -> 0 | M3: =$F3*Outputs_Internal!$D$51/12 -> 0 | N3: =$F3*Outputs_Internal!K$51/12 -> 0 | O3: =$F3*Outputs_Internal!L$51/12 -> 0 | P3: =$F3*Outputs_Internal!M$51/12 -> 0 | Q3: =$F3*Outputs_Internal!N$51/12 -> 0
B4: =EDATE(B3,1) -> 42948 | D4: =D3*IF(AND(MONTH(B4)=1,YEAR(B4)>=YEAR(Prices!$I$15)),1+Prices!$I$14,1) -> 1 | E4: =IF(B4=Inputs!$C$1,D4,E3) -> 1 | F4: =IF(AND(B4>=Inputs!$C$1,B4<EDATE(Inputs!$C$1,Inputs!$C$2)),E4,0) -> 0 | H4: =IF($B4=Inputs!$C$1,SUM(Outputs_Internal!$D$4, Outputs_Internal!$D$5),0)*$D4 -> 0 | I4: =IF($B4=Inputs!$C$1,SUM(Outputs_Internal!K$4, Outputs_Internal!K$5),0)*$D4 -> 0 | J4: =IF($B4=Inputs!$C$1,SUM(Outputs_Internal!L$4, Outputs_Internal!L$5),0)*$D4 -> 0 | K4: =IF($B4=Inputs!$C$1,SUM(Outputs_Internal!M$4, Outputs_Internal!$M$5),0)*$D4 -> 0 | M4: =$F4*Outputs_Internal!$D$51/12 -> 0 | N4: =$F4*Outputs_Internal!K$51/12 -> 0 | O4: =$F4*Outputs_Internal!L$51/12 -> 0 | P4: =$F4*Outputs_Internal!M$51/12 -> 0 | Q4: =$F4*Outputs_Internal!N$51/12 -> 0
B5: =EDATE(B4,1) -> 42979 | D5: =D4*IF(AND(MONTH(B5)=1,YEAR(B5)>=YEAR(Prices!$I$15)),1+Prices!$I$14,1) -> 1 | E5: =IF(B5=Inputs!$C$1,D5,E4) -> 1 | F5: =IF(AND(B5>=Inputs!$C$1,B5<EDATE(Inputs!$C$1,Inputs!$C$2)),E5,0) -> 0 | H5: =IF($B5=Inputs!$C$1,SUM(Outputs_Internal!$D$4, Outputs_Internal!$D$5),0)*$D5 -> 0 | I5: =IF($B5=Inputs!$C$1,SUM(Outputs_Internal!K$4, Outputs_Internal!K$5),0)*$D5 -> 0 | J5: =IF($B5=Inputs!$C$1,SUM(Outputs_Internal!L$4, Outputs_Internal!L$5),0)*$D5 -> 0 | K5: =IF($B5=Inputs!$C$1,SUM(Outputs_Internal!M$4, Outputs_Internal!$M$5),0)*$D5 -> 0 | M5: =$F5*Outputs_Internal!$D$51/12 -> 0 | N5: =$F5*Outputs_Internal!K$51/12 -> 0 | O5: =$F5*Outputs_Internal!L$51/12 -> 0 | P5: =$F5*Outputs_Internal!M$51/12 -> 0 | Q5: =$F5*Outputs_Internal!N$51/12 -> 0 | S5: =IF(MOD(MONTH($B5),3)=0,SUM(H3:H5,M3:M5),0) -> 0 | T5: =IF(MOD(MONTH($B5),3)=0,SUM(I3:I5,N3:N5),0) -> 0 | U5: =IF(MOD(MONTH($B5),3)=0,SUM(J3:J5,O3:O5),0) -> 0 | V5: =IF(MOD(MONTH($B5),3)=0,SUM(K3:K5,P3:P5),0) -> 0 | W5: =IF(MOD(MONTH($B5),3)=0,SUM(L3:L5,Q3:Q5),0) -> 0
B6: =EDATE(B5,1) -> 43009 | D6: =D5*IF(AND(MONTH(B6)=1,YEAR(B6)>=YEAR(Prices!$I$15)),1+Prices!$I$14,1) -> 1 | E6: =IF(B6=Inputs!$C$1,D6,E5) -> 1 | F6: =IF(AND(B6>=Inputs!$C$1,B6<EDATE(Inputs!$C$1,Inputs!$C$2)),E6,0) -> 0 | H6: =IF($B6=Inputs!$C$1,SUM(Outputs_Internal!$D$4, Outputs_Internal!$D$5),0)*$D6 -> 0 | I6: =IF($B6=Inputs!$C$1,SUM(Outputs_Internal!K$4, Outputs_Internal!K$5),0)*$D6 -> 0 | J6: =IF($B6=Inputs!$C$1,SUM(Outputs_Internal!L$4, Outputs_Internal!L$5),0)*$D6 -> 0 | K6: =IF($B6=Inputs!$C$1,SUM(Outputs_Internal!M$4, Outputs_Internal!$M$5),0)*$D6 -> 0 | M6: =$F6*Outputs_Internal!$D$51/12 -> 0 | N6: =$F6*Outputs_Internal!K$51/12 -> 0 | O6: =$F6*Outputs_Internal!L$51/12 -> 0 | P6: =$F6*Outputs_Internal!M$51/12 -> 0 | Q6: =$F6*Outputs_Internal!N$51/12 -> 0 | S6: =IF(MOD(MONTH($B6),3)=0,SUM(H4:H6,M4:M6),0) -> 0 | T6: =IF(MOD(MONTH($B6),3)=0,SUM(I4:I6,N4:N6),0) -> 0 | U6: =IF(MOD(MONTH($B6),3)=0,SUM(J4:J6,O4:O6),0) -> 0 | V6: =IF(MOD(MONTH($B6),3)=0,SUM(K4:K6,P4:P6),0) -> 0 | W6: =IF(MOD(MONTH($B6),3)=0,SUM(L4:L6,Q4:Q6),0) -> 0
B7: =EDATE(B6,1) -> 43040 | D7: =D6*IF(AND(MONTH(B7)=1,YEAR(B7)>=YEAR(Prices!$I$15)),1+Prices!$I$14,1) -> 1 | E7: =IF(B7=Inputs!$C$1,D7,E6) -> 1 | F7: =IF(AND(B7>=Inputs!$C$1,B7<EDATE(Inputs!$C$1,Inputs!$C$2)),E7,0) -> 0 | H7: =IF($B7=Inputs!$C$1,SUM(Outputs_Internal!$D$4, Outputs_Internal!$D$5),0)*$D7 -> 0 | I7: =IF($B7=Inputs!$C$1,SUM(Outputs_Internal!K$4, Outputs_Internal!K$5),0)*$D7 -> 0 | J7: =IF($B7=Inputs!$C$1,SUM(Outputs_Internal!L$4, Outputs_Internal!L$5),0)*$D7 -> 0 | K7: =IF($B7=Inputs!$C$1,SUM(Outputs_Internal!M$4, Outputs_Internal!$M$5),0)*$D7 -> 0 | M7: =$F7*Outputs_Internal!$D$51/12 -> 0 | N7: =$F7*Outputs_Internal!K$51/12 -> 0 | O7: =$F7*Outputs_Internal!L$51/12 -> 0 | P7: =$F7*Outputs_Internal!M$51/12 -> 0 | Q7: =$F7*Outputs_Internal!N$51/12 -> 0 | S7: =IF(MOD(MONTH($B7),3)=0,SUM(H5:H7,M5:M7),0) -> 0 | T7: =IF(MOD(MONTH($B7),3)=0,SUM(I5:I7,N5:N7),0) -> 0 | U7: =IF(MOD(MONTH($B7),3)=0,SUM(J5:J7,O5:O7),0) -> 0 | V7: =IF(MOD(MONTH($B7),3)=0,SUM(K5:K7,P5:P7),0) -> 0 | W7: =IF(MOD(MONTH($B7),3)=0,SUM(L5:L7,Q5:Q7),0) -> 0
B8: =EDATE(B7,1) -> 43070 | D8: =D7*IF(AND(MONTH(B8)=1,YEAR(B8)>=YEAR(Prices!$I$15)),1+Prices!$I$14,1) -> 1 | E8: =IF(B8=Inputs!$C$1,D8,E7) -> 1 | F8: =IF(AND(B8>=Inputs!$C$1,B8<EDATE(Inputs!$C$1,Inputs!$C$2)),E8,0) -> 0 | H8: =IF($B8=Inputs!$C$1,SUM(Outputs_Internal!$D$4, Outputs_Internal!$D$5),0)*$D8 -> 0 | I8: =IF($B8=Inputs!$C$1,SUM(Outputs_Internal!K$4, Outputs_Internal!K$5),0)*$D8 -> 0 | J8: =IF($B8=Inputs!$C$1,SUM(Outputs_Internal!L$4, Outputs_Internal!L$5),0)*$D8 -> 0 | K8: =IF($B8=Inputs!$C$1,SUM(Outputs_Internal!M$4, Outputs_Internal!$M$5),0)*$D8 -> 0 | M8: =$F8*Outputs_Internal!$D$51/12 -> 0 | N8: =$F8*Outputs_Internal!K$51/12 -> 0 | O8: =$F8*Outputs_Internal!L$51/12 -> 0 | P8: =$F8*Outputs_Internal!M$51/12 -> 0 | Q8: =$F8*Outputs_Internal!N$51/12 -> 0 | S8: =IF(MOD(MONTH($B8),3)=0,SUM(H6:H8,M6:M8),0) -> 0 | T8: =IF(MOD(MONTH($B8),3)=0,SUM(I6:I8,N6:N8),0) -> 0 | U8: =IF(MOD(MONTH($B8),3)=0,SUM(J6:J8,O6:O8),0) -> 0 | V8: =IF(MOD(MONTH($B8),3)=0,SUM(K6:K8,P6:P8),0) -> 0 | W8: =IF(MOD(MONTH($B8),3)=0,SUM(L6:L8,Q6:Q8),0) -> 0
B9: =EDATE(B8,1) -> 43101 | D9: =D8*IF(AND(MONTH(B9)=1,YEAR(B9)>=YEAR(Prices!$I$15)),1+Prices!$I$14,1) -> 1 | E9: =IF(B9=Inputs!$C$1,D9,E8) -> 1 | F9: =IF(AND(B9>=Inputs!$C$1,B9<EDATE(Inputs!$C$1,Inputs!$C$2)),E9,0) -> 1 | H9: =IF($B9=Inputs!$C$1,SUM(Outputs_Internal!$D$4, Outputs_Internal!$D$5),0)*$D9 -> 5000 | I9: =IF($B9=Inputs!$C$1,SUM(Outputs_Internal!K$4, Outputs_Internal!K$5),0)*$D9 -> 2500 | J9: =IF($B9=Inputs!$C$1,SUM(Outputs_Internal!L$4, Outputs_Internal!L$5),0)*$D9 -> 2500 | K9: =IF($B9=Inputs!$C$1,SUM(Outputs_Internal!M$4, Outputs_Internal!$M$5),0)*$D9 -> 0 | M9: =$F9*Outputs_Internal!$D$51/12+(7250/12) -> 4679.1667 | N9: =$F9*Outputs_Internal!K$51/12+(6525/12) -> 1968.75 | O9: =$F9*Outputs_Internal!L$51/12+(725/12) -> 2190.4167 | P9: =$F9*Outputs_Internal!M$51/12 -> 480 | Q9: =$F9*Outputs_Internal!N$51/12 -> 40 | S9: =IF(MOD(MONTH($B9),3)=0,SUM(H7:H9,M7:M9),0) -> 0 | T9: =IF(MOD(MONTH($B9),3)=0,SUM(I7:I9,N7:N9),0) -> 0 | U9: =IF(MOD(MONTH($B9),3)=0,SUM(J7:J9,O7:O9),0) -> 0 | V9: =IF(MOD(MONTH($B9),3)=0,SUM(K7:K9,P7:P9),0) -> 0 | W9: =IF(MOD(MONTH($B9),3)=0,SUM(L7:L9,Q7:Q9),0) -> 0
B10: =EDATE(B9,1) -> 43132 | D10: =D9*IF(AND(MONTH(B10)=1,YEAR(B10)>=YEAR(Prices!$I$15)),1+Prices!$I$14,1) -> 1 | E10: =IF(B10=Inputs!$C$1,D10,E9) -> 1 | F10: =IF(AND(B10>=Inputs!$C$1,B10<EDATE(Inputs!$C$1,Inputs!$C$2)),E10,0) -> 1 | H10: =IF($B10=Inputs!$C$1,SUM(Outputs_Internal!$D$4, Outputs_Internal!$D$5),0)*$D10 -> 0 | I10: =IF($B10=Inputs!$C$1,SUM(Outputs_Internal!K$4, Outputs_Internal!K$5),0)*$D10 -> 0 | J10: =IF($B10=Inputs!$C$1,SUM(Outputs_Internal!L$4, Outputs_Internal!L$5),0)*$D10 -> 0 | K10: =IF($B10=Inputs!$C$1,SUM(Outputs_Internal!M$4, Outputs_Internal!$M$5),0)*$D10 -> 0 | M10: =$F10*Outputs_Internal!$D$51/12+(7250/12) -> 4679.1667 | N10: =$F10*Outputs_Internal!K$51/12+(6525/12) -> 1968.75 | O10: =$F10*Outputs_Internal!L$51/12+(725/12) -> 2190.4167 | P10: =$F10*Outputs_Internal!M$51/12 -> 480 | Q10: =$F10*Outputs_Internal!N$51/12 -> 40 | S10: =IF(MOD(MONTH($B10),3)=0,SUM(H8:H10,M8:M10),0) -> 0 | T10: =IF(MOD(MONTH($B10),3)=0,SUM(I8:I10,N8:N10),0) -> 0 | U10: =IF(MOD(MONTH($B10),3)=0,SUM(J8:J10,O8:O10),0) -> 0 | V10: =IF(MOD(MONTH($B10),3)=0,SUM(K8:K10,P8:P10),0) -> 0 | W10: =IF(MOD(MONTH($B10),3)=0,SUM(L8:L10,Q8:Q10),0) -> 0
B11: =EDATE(B10,1) -> 43160 | D11: =D10*IF(AND(MONTH(B11)=1,YEAR(B11)>=YEAR(Prices!$I$15)),1+Prices!$I$14,1) -> 1 | E11: =IF(B11=Inputs!$C$1,D11,E10) -> 1 | F11: =IF(AND(B11>=Inputs!$C$1,B11<EDATE(Inputs!$C$1,Inputs!$C$2)),E11,0) -> 1 | H11: =IF($B11=Inputs!$C$1,SUM(Outputs_Internal!$D$4, Outputs_Internal!$D$5),0)*$D11 -> 0 | I11: =IF($B11=Inputs!$C$1,SUM(Outputs_Internal!K$4, Outputs_Internal!K$5),0)*$D11 -> 0 | J11: =IF($B11=Inputs!$C$1,SUM(Outputs_Internal!L$4, Outputs_Internal!L$5),0)*$D11 -> 0 | K11: =IF($B11=Inputs!$C$1,SUM(Outputs_Internal!M$4, Outputs_Internal!$M$5),0)*$D11 -> 0 | M11: =$F11*Outputs_Internal!$D$51/12+(7250/12) -> 4679.1667 | N11: =$F11*Outputs_Internal!K$51/12+(6525/12) -> 1968.75 | O11: =$F11*Outputs_Internal!L$51/12+(725/12) -> 2190.4167 | P11: =$F11*Outputs_Internal!M$51/12 -> 480 | Q11: =$F11*Outputs_Internal!N$51/12 -> 40 | S11: =IF(MOD(MONTH($B11),3)=0,SUM(H9:H11,M9:M11),0) -> 19037.5 | T11: =IF(MOD(MONTH($B11),3)=0,SUM(I9:I11,N9:N11),0) -> 8406.25 | U11: =IF(MOD(MONTH($B11),3)=0,SUM(J9:J11,O9:O11),0) -> 9071.25 | V11: =IF(MOD(MONTH($B11),3)=0,SUM(K9:K11,P9:P11),0) -> 1440 | W11: =IF(MOD(MONTH($B11),3)=0,SUM(L9:L11,Q9:Q11),0) -> 120
B12: =EDATE(B11,1) -> 43191 | D12: =D11*IF(AND(MONTH(B12)=1,YEAR(B12)>=YEAR(Prices!$I$15)),1+Prices!$I$14,1) -> 1 | E12: =IF(B12=Inputs!$C$1,D12,E11) -> 1 | F12: =IF(AND(B12>=Inputs!$C$1,B12<EDATE(Inputs!$C$1,Inputs!$C$2)),E12,0) -> 1 | H12: =IF($B12=Inputs!$C$1,SUM(Outputs_Internal!$D$4, Outputs_Internal!$D$5),0)*$D12 -> 0 | I12: =IF($B12=Inputs!$C$1,SUM(Outputs_Internal!K$4, Outputs_Internal!K$5),0)*$D12 -> 0 | J12: =IF($B12=Inputs!$C$1,SUM(Outputs_Internal!L$4, Outputs_Internal!L$5),0)*$D12 -> 0 | K12: =IF($B12=Inputs!$C$1,SUM(Outputs_Internal!M$4, Outputs_Internal!$M$5),0)*$D12 -> 0 | M12: =$F12*Outputs_Internal!$D$51/12+(7250/12) -> 4679.1667 | N12: =$F12*Outputs_Internal!K$51/12+(6525/12) -> 1968.75 | O12: =$F12*Outputs_Internal!L$51/12+(725/12) -> 2190.4167 | P12: =$F12*Outputs_Internal!M$51/12 -> 480 | Q12: =$F12*Outputs_Internal!N$51/12 -> 40 | S12: =IF(MOD(MONTH($B12),3)=0,SUM(H10:H12,M10:M12),0) -> 0 | T12: =IF(MOD(MONTH($B12),3)=0,SUM(I10:I12,N10:N12),0) -> 0 | U12: =IF(MOD(MONTH($B12),3)=0,SUM(J10:J12,O10:O12),0) -> 0 | V12: =IF(MOD(MONTH($B12),3)=0,SUM(K10:K12,P10:P12),0) -> 0 | W12: =IF(MOD(MONTH($B12),3)=0,SUM(L10:L12,Q10:Q12),0) -> 0
B13: =EDATE(B12,1) -> 43221 | D13: =D12*IF(AND(MONTH(B13)=1,YEAR(B13)>=YEAR(Prices!$I$15)),1+Prices!$I$14,1) -> 1 | E13: =IF(B13=Inputs!$C$1,D13,E12) -> 1 | F13: =IF(AND(B13>=Inputs!$C$1,B13<EDATE(Inputs!$C$1,Inputs!$C$2)),E13,0) -> 1 | H13: =IF($B13=Inputs!$C$1,SUM(Outputs_Internal!$D$4, Outputs_Internal!$D$5),0)*$D13 -> 0 | I13: =IF($B13=Inputs!$C$1,SUM(Outputs_Internal!K$4, Outputs_Internal!K$5),0)*$D13 -> 0 | J13: =IF($B13=Inputs!$C$1,SUM(Outputs_Internal!L$4, Outputs_Internal!L$5),0)*$D13 -> 0 | K13: =IF($B13=Inputs!$C$1,SUM(Outputs_Internal!M$4, Outputs_Internal!$M$5),0)*$D13 -> 0 | M13: =$F13*Outputs_Internal!$D$51/12+(7250/12) -> 4679.1667 | N13: =$F13*Outputs_Internal!K$51/12+(6525/12) -> 1968.75 | O13: =$F13*Outputs_Internal!L$51/12+(725/12) -> 2190.4167 | P13: =$F13*Outputs_Internal!M$51/12 -> 480 | Q13: =$F13*Outputs_Internal!N$51/12 -> 40 | S13: =IF(MOD(MONTH($B13),3)=0,SUM(H11:H13,M11:M13),0) -> 0 | T13: =IF(MOD(MONTH($B13),3)=0,SUM(I11:I13,N11:N13),0) -> 0 | U13: =IF(MOD(MONTH($B13),3)=0,SUM(J11:J13,O11:O13),0) -> 0 | V13: =IF(MOD(MONTH($B13),3)=0,SUM(K11:K13,P11:P13),0) -> 0 | W13: =IF(MOD(MONTH($B13),3)=0,SUM(L11:L13,Q11:Q13),0) -> 0
B14: =EDATE(B13,1) -> 43252 | D14: =D13*IF(AND(MONTH(B14)=1,YEAR(B14)>=YEAR(Prices!$I$15)),1+Prices!$I$14,1) -> 1 | E14: =IF(B14=Inputs!$C$1,D14,E13) -> 1 | F14: =IF(AND(B14>=Inputs!$C$1,B14<EDATE(Inputs!$C$1,Inputs!$C$2)),E14,0) -> 1 | H14: =IF($B14=Inputs!$C$1,SUM(Outputs_Internal!$D$4, Outputs_Internal!$D$5),0)*$D14 -> 0 | I14: =IF($B14=Inputs!$C$1,SUM(Outputs_Internal!K$4, Outputs_Internal!K$5),0)*$D14 -> 0 | J14: =IF($B14=Inputs!$C$1,SUM(Outputs_Internal!L$4, Outputs_Internal!L$5),0)*$D14 -> 0 | K14: =IF($B14=Inputs!$C$1,SUM(Outputs_Internal!M$4, Outputs_Internal!$M$5),0)*$D14 -> 0 | M14: =$F14*Outputs_Internal!$D$51/12+(7250/12) -> 4679.1667 | N14: =$F14*Outputs_Internal!K$51/12+(6525/12) -> 1968.75 | O14: =$F14*Outputs_Internal!L$51/12+(725/12) -> 2190.4167 | P14: =$F14*Outputs_Internal!M$51/12 -> 480 | Q14: =$F14*Outputs_Internal!N$51/12 -> 40 | S14: =IF(MOD(MONTH($B14),3)=0,SUM(H12:H14,M12:M14),0) -> 14037.5 | T14: =IF(MOD(MONTH($B14),3)=0,SUM(I12:I14,N12:N14),0) -> 5906.25 | U14: =IF(MOD(MONTH($B14),3)=0,SUM(J12:J14,O12:O14),0) -> 6571.25 | V14: =IF(MOD(MONTH($B14),3)=0,SUM(K12:K14,P12:P14),0) -> 1440 | W14: =IF(MOD(MONTH($B14),3)=0,SUM(L12:L14,Q12:Q14),0) -> 120
B15: =EDATE(B14,1) -> 43282 | D15: =D14*IF(AND(MONTH(B15)=1,YEAR(B15)>=YEAR(Prices!$I$15)),1+Prices!$I$14,1) -> 1 | E15: =IF(B15=Inputs!$C$1,D15,E14) -> 1 | F15: =IF(AND(B15>=Inputs!$C$1,B15<EDATE(Inputs!$C$1,Inputs!$C$2)),E15,0) -> 1 | H15: =IF($B15=Inputs!$C$1,SUM(Outputs_Internal!$D$4, Outputs_Internal!$D$5),0)*$D15 -> 0 | I15: =IF($B15=Inputs!$C$1,SUM(Outputs_Internal!K$4, Outputs_Internal!K$5),0)*$D15 -> 0 | J15: =IF($B15=Inputs!$C$1,SUM(Outputs_Internal!L$4, Outputs_Internal!L$5),0)*$D15 -> 0 | K15: =IF($B15=Inputs!$C$1,SUM(Outputs_Internal!M$4, Outputs_Internal!$M$5),0)*$D15 -> 0 | M15: =$F15*Outputs_Internal!$D$51/12+(7250/12) -> 4679.1667 | N15: =$F15*Outputs_Internal!K$51/12+(6525/12) -> 1968.75 | O15: =$F15*Outputs_Internal!L$51/12+(725/12) -> 2190.4167 | P15: =$F15*Outputs_Internal!M$51/12 -> 480 | Q15: =$F15*Outputs_Internal!N$51/12 -> 40 | S15: =IF(MOD(MONTH($B15),3)=0,SUM(H13:H15,M13:M15),0) -> 0 | T15: =IF(MOD(MONTH($B15),3)=0,SUM(I13:I15,N13:N15),0) -> 0 | U15: =IF(MOD(MONTH($B15),3)=0,SUM(J13:J15,O13:O15),0) -> 0 | V15: =IF(MOD(MONTH($B15),3)=0,SUM(K13:K15,P13:P15),0) -> 0 | W15: =IF(MOD(MONTH($B15),3)=0,SUM(L13:L15,Q13:Q15),0) -> 0
B16: =EDATE(B15,1) -> 43313 | D16: =D15*IF(AND(MONTH(B16)=1,YEAR(B16)>=YEAR(Prices!$I$15)),1+Prices!$I$14,1) -> 1 | E16: =IF(B16=Inputs!$C$1,D16,E15) -> 1 | F16: =IF(AND(B16>=Inputs!$C$1,B16<EDATE(Inputs!$C$1,Inputs!$C$2)),E16,0) -> 1 | H16: =IF($B16=Inputs!$C$1,SUM(Outputs_Internal!$D$4, Outputs_Internal!$D$5),0)*$D16 -> 0 | I16: =IF($B16=Inputs!$C$1,SUM(Outputs_Internal!K$4, Outputs_Internal!K$5),0)*$D16 -> 0 | J16: =IF($B16=Inputs!$C$1,SUM(Outputs_Internal!L$4, Outputs_Internal!L$5),0)*$D16 -> 0 | K16: =IF($B16=Inputs!$C$1,SUM(Outputs_Internal!M$4, Outputs_Internal!$M$5),0)*$D16 -> 0 | M16: =$F16*Outputs_Internal!$D$51/12+(7250/12) -> 4679.1667 | N16: =$F16*Outputs_Internal!K$51/12+(6525/12) -> 1968.75 | O16: =$F16*Outputs_Internal!L$51/12+(725/12) -> 2190.4167 | P16: =$F16*Outputs_Internal!M$51/12 -> 480 | Q16: =$F16*Outputs_Internal!N$51/12 -> 40 | S16: =IF(MOD(MONTH($B16),3)=0,SUM(H14:H16,M14:M16),0) -> 0 | T16: =IF(MOD(MONTH($B16),3)=0,SUM(I14:I16,N14:N16),0) -> 0 | U16: =IF(MOD(MONTH($B16),3)=0,SUM(J14:J16,O14:O16),0) -> 0 | V16: =IF(MOD(MONTH($B16),3)=0,SUM(K14:K16,P14:P16),0) -> 0 | W16: =IF(MOD(MONTH($B16),3)=0,SUM(L14:L16,Q14:Q16),0) -> 0
B17: =EDATE(B16,1) -> 43344 | D17: =D16*IF(AND(MONTH(B17)=1,YEAR(B17)>=YEAR(Prices!$I$15)),1+Prices!$I$14,1) -> 1 | E17: =IF(B17=Inputs!$C$1,D17,E16) -> 1 | F17: =IF(AND(B17>=Inputs!$C$1,B17<EDATE(Inputs!$C$1,Inputs!$C$2)),E17,0) -> 1 | H17: =IF($B17=Inputs!$C$1,SUM(Outputs_Internal!$D$4, Outputs_Internal!$D$5),0)*$D17 -> 0 | I17: =IF($B17=Inputs!$C$1,SUM(Outputs_Internal!K$4, Outputs_Internal!K$5),0)*$D17 -> 0 | J17: =IF($B17=Inputs!$C$1,SUM(Outputs_Internal!L$4, Outputs_Internal!L$5),0)*$D17 -> 0 | K17: =IF($B17=Inputs!$C$1,SUM(Outputs_Internal!M$4, Outputs_Internal!$M$5),0)*$D17 -> 0 | M17: =$F17*Outputs_Internal!$D$51/12+(7250/12) -> 4679.1667 | N17: =$F17*Outputs_Internal!K$51/12+(6525/12) -> 1968.75 | O17: =$F17*Outputs_Internal!L$51/12+(725/12) -> 2190.4167 | P17: =$F17*Outputs_Internal!M$51/12 -> 480 | Q17: =$F17*Outputs_Internal!N$51/12 -> 40 | S17: =IF(MOD(MONTH($B17),3)=0,SUM(H15:H17,M15:M17),0) -> 14037.5 | T17: =IF(MOD(MONTH($B17),3)=0,SUM(I15:I17,N15:N17),0) -> 5906.25 | U17: =IF(MOD(MONTH($B17),3)=0,SUM(J15:J17,O15:O17),0) -> 6571.25 | V17: =IF(MOD(MONTH($B17),3)=0,SUM(K15:K17,P15:P17),0) -> 1440 | W17: =IF(MOD(MONTH($B17),3)=0,SUM(L15:L17,Q15:Q17),0) -> 120
B18: =EDATE(B17,1) -> 43374 | D18: =D17*IF(AND(MONTH(B18)=1,YEAR(B18)>=YEAR(Prices!$I$15)),1+Prices!$I$14,1) -> 1 | E18: =IF(B18=Inputs!$C$1,D18,E17) -> 1 | F18: =IF(AND(B18>=Inputs!$C$1,B18<EDATE(Inputs!$C$1,Inputs!$C$2)),E18,0) -> 1 | H18: =IF($B18=Inputs!$C$1,SUM(Outputs_Internal!$D$4, Outputs_Internal!$D$5),0)*$D18 -> 0 | I18: =IF($B18=Inputs!$C$1,SUM(Outputs_Internal!K$4, Outputs_Internal!K$5),0)*$D18 -> 0 | J18: =IF($B18=Inputs!$C$1,SUM(Outputs_Internal!L$4, Outputs_Internal!L$5),0)*$D18 -> 0 | K18: =IF($B18=Inputs!$C$1,SUM(Outputs_Internal!M$4, Outputs_Internal!$M$5),0)*$D18 -> 0 | M18: =$F18*Outputs_Internal!$D$51/12+(7250/12) -> 4679.1667 | N18: =$F18*Outputs_Internal!K$51/12+(6525/12) -> 1968.75 | O18: =$F18*Outputs_Internal!L$51/12+(725/12) -> 2190.4167 | P18: =$F18*Outputs_Internal!M$51/12 -> 480 | Q18: =$F18*Outputs_Internal!N$51/12 -> 40 | S18: =IF(MOD(MONTH($B18),3)=0,SUM(H16:H18,M16:M18),0) -> 0 | T18: =IF(MOD(MONTH($B18),3)=0,SUM(I16:I18,N16:N18),0) -> 0 | U18: =IF(MOD(MONTH($B18),3)=0,SUM(J16:J18,O16:O18),0) -> 0 | V18: =IF(MOD(MONTH($B18),3)=0,SUM(K16:K18,P16:P18),0) -> 0 | W18: =IF(MOD(MONTH($B18),3)=0,SUM(L16:L18,Q16:Q18),0) -> 0
B19: =EDATE(B18,1) -> 43405 | D19: =D18*IF(AND(MONTH(B19)=1,YEAR(B19)>=YEAR(Prices!$I$15)),1+Prices!$I$14,1) -> 1 | E19: =IF(B19=Inputs!$C$1,D19,E18) -> 1 | F19: =IF(AND(B19>=Inputs!$C$1,B19<EDATE(Inputs!$C$1,Inputs!$C$2)),E19,0) -> 1 | H19: =IF($B19=Inputs!$C$1,SUM(Outputs_Internal!$D$4, Outputs_Internal!$D$5),0)*$D19 -> 0 | I19: =IF($B19=Inputs!$C$1,SUM(Outputs_Internal!K$4, Outputs_Internal!K$5),0)*$D19 -> 0 | J19: =IF($B19=Inputs!$C$1,SUM(Outputs_Internal!L$4, Outputs_Internal!L$5),0)*$D19 -> 0 | K19: =IF($B19=Inputs!$C$1,SUM(Outputs_Internal!M$4, Outputs_Internal!$M$5),0)*$D19 -> 0 | M19: =$F19*Outputs_Internal!$D$51/12+(7250/12) -> 4679.1667 | N19: =$F19*Outputs_Internal!K$51/12+(6525/12) -> 1968.75 | O19: =$F19*Outputs_Internal!L$51/12+(725/12) -> 2190.4167 | P19: =$F19*Outputs_Internal!M$51/12 -> 480 | Q19: =$F19*Outputs_Internal!N$51/12 -> 40 | S19: =IF(MOD(MONTH($B19),3)=0,SUM(H17:H19,M17:M19),0) -> 0 | T19: =IF(MOD(MONTH($B19),3)=0,SUM(I17:I19,N17:N19),0) -> 0 | U19: =IF(MOD(MONTH($B19),3)=0,SUM(J17:J19,O17:O19),0) -> 0 | V19: =IF(MOD(MONTH($B19),3)=0,SUM(K17:K19,P17:P19),0) -> 0 | W19: =IF(MOD(MONTH($B19),3)=0,SUM(L17:L19,Q17:Q19),0) -> 0
B20: =EDATE(B19,1) -> 43435 | D20: =D19*IF(AND(MONTH(B20)=1,YEAR(B20)>=YEAR(Prices!$I$15)),1+Prices!$I$14,1) -> 1 | E20: =IF(B20=Inputs!$C$1,D20,E19) -> 1 | F20: =IF(AND(B20>=Inputs!$C$1,B20<EDATE(Inputs!$C$1,Inputs!$C$2)),E20,0) -> 1 | H20: =IF($B20=Inputs!$C$1,SUM(Outputs_Internal!$D$4, Outputs_Internal!$D$5),0)*$D20 -> 0 | I20: =IF($B20=Inputs!$C$1,SUM(Outputs_Internal!K$4, Outputs_Internal!K$5),0)*$D20 -> 0 | J20: =IF($B20=Inputs!$C$1,SUM(Outputs_Internal!L$4, Outputs_Internal!L$5),0)*$D20 -> 0 | K20: =IF($B20=Inputs!$C$1,SUM(Outputs_Internal!M$4, Outputs_Internal!$M$5),0)*$D20 -> 0 | M20: =$F20*Outputs_Internal!$D$51/12+(7250/12) -> 4679.1667 | N20: =$F20*Outputs_Internal!K$51/12+(6525/12) -> 1968.75 | O20: =$F20*Outputs_Internal!L$51/12+(725/12) -> 2190.4167 | P20: =$F20*Outputs_Internal!M$51/12 -> 480 | Q20: =$F20*Outputs_Internal!N$51/12 -> 40 | S20: =IF(MOD(MONTH($B20),3)=0,SUM(H18:H20,M18:M20),0) -> 14037.5 | T20: =IF(MOD(MONTH($B20),3)=0,SUM(I18:I20,N18:N20),0) -> 5906.25 | U20: =IF(MOD(MONTH($B20),3)=0,SUM(J18:J20,O18:O20),0) -> 6571.25 | V20: =IF(MOD(MONTH($B20),3)=0,SUM(K18:K20,P18:P20),0) -> 1440 | W20: =IF(MOD(MONTH($B20),3)=0,SUM(L18:L20,Q18:Q20),0) -> 120
B21: =EDATE(B20,1) -> 43466 | D21: =D20*IF(AND(MONTH(B21)=1,YEAR(B21)>=YEAR(Prices!$I$15)),1+Prices!$I$14,1) -> 1.0125 | E21: =IF(B21=Inputs!$C$1,D21,E20) -> 1 | F21: =IF(AND(B21>=Inputs!$C$1,B21<EDATE(Inputs!$C$1,Inputs!$C$2)),E21,0) -> 0 | H21: =IF($B21=Inputs!$C$1,SUM(Outputs_Internal!$D$4, Outputs_Internal!$D$5),0)*$D21 -> 0 | I21: =IF($B21=Inputs!$C$1,SUM(Outputs_Internal!K$4, Outputs_Internal!K$5),0)*$D21 -> 0 | J21: =IF($B21=Inputs!$C$1,SUM(Outputs_Internal!L$4, Outputs_Internal!L$5),0)*$D21 -> 0 | K21: =IF($B21=Inputs!$C$1,SUM(Outputs_Internal!M$4, Outputs_Internal!$M$5),0)*$D21 -> 0 | M21: =$F21*Outputs_Internal!$D$51/12 -> 0 | N21: =$F21*Outputs_Internal!K$51/12 -> 0 | O21: =$F21*Outputs_Internal!L$51/12 -> 0 | P21: =$F21*Outputs_Internal!M$51/12 -> 0 | Q21: =$F21*Outputs_Internal!N$51/12 -> 0 | S21: =IF(MOD(MONTH($B21),3)=0,SUM(H19:H21,M19:M21),0) -> 0 | T21: =IF(MOD(MONTH($B21),3)=0,SUM(I19:I21,N19:N21),0) -> 0 | U21: =IF(MOD(MONTH($B21),3)=0,SUM(J19:J21,O19:O21),0) -> 0 | V21: =IF(MOD(MONTH($B21),3)=0,SUM(K19:K21,P19:P21),0) -> 0 | W21: =IF(MOD(MONTH($B21),3)=0,SUM(L19:L21,Q19:Q21),0) -> 0
B22: =EDATE(B21,1) -> 43497 | D22: =D21*IF(AND(MONTH(B22)=1,YEAR(B22)>=YEAR(Prices!$I$15)),1+Prices!$I$14,1) -> 1.0125 | E22: =IF(B22=Inputs!$C$1,D22,E21) -> 1 | F22: =IF(AND(B22>=Inputs!$C$1,B22<EDATE(Inputs!$C$1,Inputs!$C$2)),E22,0) -> 0 | H22: =IF($B22=Inputs!$C$1,SUM(Outputs_Internal!$D$4, Outputs_Internal!$D$5),0)*$D22 -> 0 | I22: =IF($B22=Inputs!$C$1,SUM(Outputs_Internal!K$4, Outputs_Internal!K$5),0)*$D22 -> 0 | J22: =IF($B22=Inputs!$C$1,SUM(Outputs_Internal!L$4, Outputs_Internal!L$5),0)*$D22 -> 0 | K22: =IF($B22=Inputs!$C$1,SUM(Outputs_Internal!M$4, Outputs_Internal!$M$5),0)*$D22 -> 0 | M22: =$F22*Outputs_Internal!$D$51/12 -> 0 | N22: =$F22*Outputs_Internal!K$51/12 -> 0 | O22: =$F22*Outputs_Internal!L$51/12 -> 0 | P22: =$F22*Outputs_Internal!M$51/12 -> 0 | Q22: =$F22*Outputs_Internal!N$51/12 -> 0 | S22: =IF(MOD(MONTH($B22),3)=0,SUM(H20:H22,M20:M22),0) -> 0 | T22: =IF(MOD(MONTH($B22),3)=0,SUM(I20:I22,N20:N22),0) -> 0 | U22: =IF(MOD(MONTH($B22),3)=0,SUM(J20:J22,O20:O22),0) -> 0 | V22: =IF(MOD(MONTH($B22),3)=0,SUM(K20:K22,P20:P22),0) -> 0 | W22: =IF(MOD(MONTH($B22),3)=0,SUM(L20:L22,Q20:Q22),0) -> 0
B23: =EDATE(B22,1) -> 43525 | D23: =D22*IF(AND(MONTH(B23)=1,YEAR(B23)>=YEAR(Prices!$I$15)),1+Prices!$I$14,1) -> 1.0125 | E23: =IF(B23=Inputs!$C$1,D23,E22) -> 1 | F23: =IF(AND(B23>=Inputs!$C$1,B23<EDATE(Inputs!$C$1,Inputs!$C$2)),E23,0) -> 0 | H23: =IF($B23=Inputs!$C$1,SUM(Outputs_Internal!$D$4, Outputs_Internal!$D$5),0)*$D23 -> 0 | I23: =IF($B23=Inputs!$C$1,SUM(Outputs_Internal!K$4, Outputs_Internal!K$5),0)*$D23 -> 0 | J23: =IF($B23=Inputs!$C$1,SUM(Outputs_Internal!L$4, Outputs_Internal!L$5),0)*$D23 -> 0 | K23: =IF($B23=Inputs!$C$1,SUM(Outputs_Internal!M$4, Outputs_Internal!$M$5),0)*$D23 -> 0 | M23: =$F23*Outputs_Internal!$D$51/12 -> 0 | N23: =$F23*Outputs_Internal!K$51/12 -> 0 | O23: =$F23*Outputs_Internal!L$51/12 -> 0 | P23: =$F23*Outputs_Internal!M$51/12 -> 0 | Q23: =$F23*Outputs_Internal!N$51/12 -> 0 | S23: =IF(MOD(MONTH($B23),3)=0,SUM(H21:H23,M21:M23),0) -> 0 | T23: =IF(MOD(MONTH($B23),3)=0,SUM(I21:I23,N21:N23),0) -> 0 | U23: =IF(MOD(MONTH($B23),3)=0,SUM(J21:J23,O21:O23),0) -> 0 | V23: =IF(MOD(MONTH($B23),3)=0,SUM(K21:K23,P21:P23),0) -> 0 | W23: =IF(MOD(MONTH($B23),3)=0,SUM(L21:L23,Q21:Q23),0) -> 0
B24: =EDATE(B23,1) -> 43556 | D24: =D23*IF(AND(MONTH(B24)=1,YEAR(B24)>=YEAR(Prices!$I$15)),1+Prices!$I$14,1) -> 1.0125 | E24: =IF(B24=Inputs!$C$1,D24,E23) -> 1 | F24: =IF(AND(B24>=Inputs!$C$1,B24<EDATE(Inputs!$C$1,Inputs!$C$2)),E24,0) -> 0 | H24: =IF($B24=Inputs!$C$1,SUM(Outputs_Internal!$D$4, Outputs_Internal!$D$5),0)*$D24 -> 0 | I24: =IF($B24=Inputs!$C$1,SUM(Outputs_Internal!K$4, Outputs_Internal!K$5),0)*$D24 -> 0 | J24: =IF($B24=Inputs!$C$1,SUM(Outputs_Internal!L$4, Outputs_Internal!L$5),0)*$D24 -> 0 | K24: =IF($B24=Inputs!$C$1,SUM(Outputs_Internal!M$4, Outputs_Internal!$M$5),0)*$D24 -> 0 | M24: =$F24*Outputs_Internal!$D$51/12 -> 0 | N24: =$F24*Outputs_Internal!K$51/12 -> 0 | O24: =$F24*Outputs_Internal!L$51/12 -> 0 | P24: =$F24*Outputs_Internal!M$51/12 -> 0 | Q24: =$F24*Outputs_Internal!N$51/12 -> 0 | S24: =IF(MOD(MONTH($B24),3)=0,SUM(H22:H24,M22:M24),0) -> 0 | T24: =IF(MOD(MONTH($B24),3)=0,SUM(I22:I24,N22:N24),0) -> 0 | U24: =IF(MOD(MONTH($B24),3)=0,SUM(J22:J24,O22:O24),0) -> 0 | V24: =IF(MOD(MONTH($B24),3)=0,SUM(K22:K24,P22:P24),0) -> 0 | W24: =IF(MOD(MONTH($B24),3)=0,SUM(L22:L24,Q22:Q24),0) -> 0
B25: =EDATE(B24,1) -> 43586 | D25: =D24*IF(AND(MONTH(B25)=1,YEAR(B25)>=YEAR(Prices!$I$15)),1+Prices!$I$14,1) -> 1.0125 | E25: =IF(B25=Inputs!$C$1,D25,E24) -> 1 | F25: =IF(AND(B25>=Inputs!$C$1,B25<EDATE(Inputs!$C$1,Inputs!$C$2)),E25,0) -> 0 | H25: =IF($B25=Inputs!$C$1,SUM(Outputs_Internal!$D$4, Outputs_Internal!$D$5),0)*$D25 -> 0 | I25: =IF($B25=Inputs!$C$1,SUM(Outputs_Internal!K$4, Outputs_Internal!K$5),0)*$D25 -> 0 | J25: =IF($B25=Inputs!$C$1,SUM(Outputs_Internal!L$4, Outputs_Internal!L$5),0)*$D25 -> 0 | K25: =IF($B25=Inputs!$C$1,SUM(Outputs_Internal!M$4, Outputs_Internal!$M$5),0)*$D25 -> 0 | M25: =$F25*Outputs_Internal!$D$51/12 -> 0 | N25: =$F25*Outputs_Internal!K$51/12 -> 0 | O25: =$F25*Outputs_Internal!L$51/12 -> 0 | P25: =$F25*Outputs_Internal!M$51/12 -> 0 | Q25: =$F25*Outputs_Internal!N$51/12 -> 0 | S25: =IF(MOD(MONTH($B25),3)=0,SUM(H23:H25,M23:M25),0) -> 0 | T25: =IF(MOD(MONTH($B25),3)=0,SUM(I23:I25,N23:N25),0) -> 0 | U25: =IF(MOD(MONTH($B25),3)=0,SUM(J23:J25,O23:O25),0) -> 0 | V25: =IF(MOD(MONTH($B25),3)=0,SUM(K23:K25,P23:P25),0) -> 0 | W25: =IF(MOD(MONTH($B25),3)=0,SUM(L23:L25,Q23:Q25),0) -> 0
B26: =EDATE(B25,1) -> 43617 | D26: =D25*IF(AND(MONTH(B26)=1,YEAR(B26)>=YEAR(Prices!$I$15)),1+Prices!$I$14,1) -> 1.0125 | E26: =IF(B26=Inputs!$C$1,D26,E25) -> 1 | F26: =IF(AND(B26>=Inputs!$C$1,B26<EDATE(Inputs!$C$1,Inputs!$C$2)),E26,0) -> 0 | H26: =IF($B26=Inputs!$C$1,SUM(Outputs_Internal!$D$4, Outputs_Internal!$D$5),0)*$D26 -> 0 | I26: =IF($B26=Inputs!$C$1,SUM(Outputs_Internal!K$4, Outputs_Internal!K$5),0)*$D26 -> 0 | J26: =IF($B26=Inputs!$C$1,SUM(Outputs_Internal!L$4, Outputs_Internal!L$5),0)*$D26 -> 0 | K26: =IF($B26=Inputs!$C$1,SUM(Outputs_Internal!M$4, Outputs_Internal!$M$5),0)*$D26 -> 0 | M26: =$F26*Outputs_Internal!$D$51/12 -> 0 | N26: =$F26*Outputs_Internal!K$51/12 -> 0 | O26: =$F26*Outputs_Internal!L$51/12 -> 0 | P26: =$F26*Outputs_Internal!M$51/12 -> 0 | Q26: =$F26*Outputs_Internal!N$51/12 -> 0 | S26: =IF(MOD(MONTH($B26),3)=0,SUM(H24:H26,M24:M26),0) -> 0 | T26: =IF(MOD(MONTH($B26),3)=0,SUM(I24:I26,N24:N26),0) -> 0 | U26: =IF(MOD(MONTH($B26),3)=0,SUM(J24:J26,O24:O26),0) -> 0 | V26: =IF(MOD(MONTH($B26),3)=0,SUM(K24:K26,P24:P26),0) -> 0 | W26: =IF(MOD(MONTH($B26),3)=0,SUM(L24:L26,Q24:Q26),0) -> 0
B27: =EDATE(B26,1) -> 43647 | D27: =D26*IF(AND(MONTH(B27)=1,YEAR(B27)>=YEAR(Prices!$I$15)),1+Prices!$I$14,1) -> 1.0125 | E27: =IF(B27=Inputs!$C$1,D27,E26) -> 1 | F27: =IF(AND(B27>=Inputs!$C$1,B27<EDATE(Inputs!$C$1,Inputs!$C$2)),E27,0) -> 0 | H27: =IF($B27=Inputs!$C$1,SUM(Outputs_Internal!$D$4, Outputs_Internal!$D$5),0)*$D27 -> 0 | I27: =IF($B27=Inputs!$C$1,SUM(Outputs_Internal!K$4, Outputs_Internal!K$5),0)*$D27 -> 0 | J27: =IF($B27=Inputs!$C$1,SUM(Outputs_Internal!L$4, Outputs_Internal!L$5),0)*$D27 -> 0 | K27: =IF($B27=Inputs!$C$1,SUM(Outputs_Internal!M$4, Outputs_Internal!$M$5),0)*$D27 -> 0 | M27: =$F27*Outputs_Internal!$D$51/12 -> 0 | N27: =$F27*Outputs_Internal!K$51/12 -> 0 | O27: =$F27*Outputs_Internal!L$51/12 -> 0 | P27: =$F27*Outputs_Internal!M$51/12 -> 0 | Q27: =$F27*Outputs_Internal!N$51/12 -> 0 | S27: =IF(MOD(MONTH($B27),3)=0,SUM(H25:H27,M25:M27),0) -> 0 | T27: =IF(MOD(MONTH($B27),3)=0,SUM(I25:I27,N25:N27),0) -> 0 | U27: =IF(MOD(MONTH($B27),3)=0,SUM(J25:J27,O25:O27),0) -> 0 | V27: =IF(MOD(MONTH($B27),3)=0,SUM(K25:K27,P25:P27),0) -> 0 | W27: =IF(MOD(MONTH($B27),3)=0,SUM(L25:L27,Q25:Q27),0) -> 0
B28: =EDATE(B27,1) -> 43678 | D28: =D27*IF(AND(MONTH(B28)=1,YEAR(B28)>=YEAR(Prices!$I$15)),1+Prices!$I$14,1) -> 1.0125 | E28: =IF(B28=Inputs!$C$1,D28,E27) -> 1 | F28: =IF(AND(B28>=Inputs!$C$1,B28<EDATE(Inputs!$C$1,Inputs!$C$2)),E28,0) -> 0 | H28: =IF($B28=Inputs!$C$1,SUM(Outputs_Internal!$D$4, Outputs_Internal!$D$5),0)*$D28 -> 0 | I28: =IF($B28=Inputs!$C$1,SUM(Outputs_Internal!K$4, Outputs_Internal!K$5),0)*$D28 -> 0 | J28: =IF($B28=Inputs!$C$1,SUM(Outputs_Internal!L$4, Outputs_Internal!L$5),0)*$D28 -> 0 | K28: =IF($B28=Inputs!$C$1,SUM(Outputs_Internal!M$4, Outputs_Internal!$M$5),0)*$D28 -> 0 | M28: =$F28*Outputs_Internal!$D$51/12 -> 0 | N28: =$F28*Outputs_Internal!K$51/12 -> 0 | O28: =$F28*Outputs_Internal!L$51/12 -> 0 | P28: =$F28*Outputs_Internal!M$51/12 -> 0 | Q28: =$F28*Outputs_Internal!N$51/12 -> 0 | S28: =IF(MOD(MONTH($B28),3)=0,SUM(H26:H28,M26:M28),0) -> 0 | T28: =IF(MOD(MONTH($B28),3)=0,SUM(I26:I28,N26:N28),0) -> 0 | U28: =IF(MOD(MONTH($B28),3)=0,SUM(J26:J28,O26:O28),0) -> 0 | V28: =IF(MOD(MONTH($B28),3)=0,SUM(K26:K28,P26:P28),0) -> 0 | W28: =IF(MOD(MONTH($B28),3)=0,SUM(L26:L28,Q26:Q28),0) -> 0
B29: =EDATE(B28,1) -> 43709 | D29: =D28*IF(AND(MONTH(B29)=1,YEAR(B29)>=YEAR(Prices!$I$15)),1+Prices!$I$14,1) -> 1.0125 | E29: =IF(B29=Inputs!$C$1,D29,E28) -> 1 | F29: =IF(AND(B29>=Inputs!$C$1,B29<EDATE(Inputs!$C$1,Inputs!$C$2)),E29,0) -> 0 | H29: =IF($B29=Inputs!$C$1,SUM(Outputs_Internal!$D$4, Outputs_Internal!$D$5),0)*$D29 -> 0 | I29: =IF($B29=Inputs!$C$1,SUM(Outputs_Internal!K$4, Outputs_Internal!K$5),0)*$D29 -> 0 | J29: =IF($B29=Inputs!$C$1,SUM(Outputs_Internal!L$4, Outputs_Internal!L$5),0)*$D29 -> 0 | K29: =IF($B29=Inputs!$C$1,SUM(Outputs_Internal!M$4, Outputs_Internal!$M$5),0)*$D29 -> 0 | M29: =$F29*Outputs_Internal!$D$51/12 -> 0 | N29: =$F29*Outputs_Internal!K$51/12 -> 0 | O29: =$F29*Outputs_Internal!L$51/12 -> 0 | P29: =$F29*Outputs_Internal!M$51/12 -> 0 | Q29: =$F29*Outputs_Internal!N$51/12 -> 0 | S29: =IF(MOD(MONTH($B29),3)=0,SUM(H27:H29,M27:M29),0) -> 0 | T29: =IF(MOD(MONTH($B29),3)=0,SUM(I27:I29,N27:N29),0) -> 0 | U29: =IF(MOD(MONTH($B29),3)=0,SUM(J27:J29,O27:O29),0) -> 0 | V29: =IF(MOD(MONTH($B29),3)=0,SUM(K27:K29,P27:P29),0) -> 0 | W29: =IF(MOD(MONTH($B29),3)=0,SUM(L27:L29,Q27:Q29),0) -> 0
B30: =EDATE(B29,1) -> 43739 | D30: =D29*IF(AND(MONTH(B30)=1,YEAR(B30)>=YEAR(Prices!$I$15)),1+Prices!$I$14,1) -> 1.0125 | E30: =IF(B30=Inputs!$C$1,D30,E29) -> 1 | F30: =IF(AND(B30>=Inputs!$C$1,B30<EDATE(Inputs!$C$1,Inputs!$C$2)),E30,0) -> 0 | H30: =IF($B30=Inputs!$C$1,SUM(Outputs_Internal!$D$4, Outputs_Internal!$D$5),0)*$D30 -> 0 | I30: =IF($B30=Inputs!$C$1,SUM(Outputs_Internal!K$4, Outputs_Internal!K$5),0)*$D30 -> 0 | J30: =IF($B30=Inputs!$C$1,SUM(Outputs_Internal!L$4, Outputs_Internal!L$5),0)*$D30 -> 0 | K30: =IF($B30=Inputs!$C$1,SUM(Outputs_Internal!M$4, Outputs_Internal!$M$5),0)*$D30 -> 0 | M30: =$F30*Outputs_Internal!$D$51/12 -> 0 | N30: =$F30*Outputs_Internal!K$51/12 -> 0 | O30: =$F30*Outputs_Internal!L$51/12 -> 0 | P30: =$F30*Outputs_Internal!M$51/12 -> 0 | Q30: =$F30*Outputs_Internal!N$51/12 -> 0 | S30: =IF(MOD(MONTH($B30),3)=0,SUM(H28:H30,M28:M30),0) -> 0 | T30: =IF(MOD(MONTH($B30),3)=0,SUM(I28:I30,N28:N30),0) -> 0 | U30: =IF(MOD(MONTH($B30),3)=0,SUM(J28:J30,O28:O30),0) -> 0 | V30: =IF(MOD(MONTH($B30),3)=0,SUM(K28:K30,P28:P30),0) -> 0 | W30: =IF(MOD(MONTH($B30),3)=0,SUM(L28:L30,Q28:Q30),0) -> 0
B31: =EDATE(B30,1) -> 43770 | D31: =D30*IF(AND(MONTH(B31)=1,YEAR(B31)>=YEAR(Prices!$I$15)),1+Prices!$I$14,1) -> 1.0125 | E31: =IF(B31=Inputs!$C$1,D31,E30) -> 1 | F31: =IF(AND(B31>=Inputs!$C$1,B31<EDATE(Inputs!$C$1,Inputs!$C$2)),E31,0) -> 0 | H31: =IF($B31=Inputs!$C$1,SUM(Outputs_Internal!$D$4, Outputs_Internal!$D$5),0)*$D31 -> 0 | I31: =IF($B31=Inputs!$C$1,SUM(Outputs_Internal!K$4, Outputs_Internal!K$5),0)*$D31 -> 0 | J31: =IF($B31=Inputs!$C$1,SUM(Outputs_Internal!L$4, Outputs_Internal!L$5),0)*$D31 -> 0 | K31: =IF($B31=Inputs!$C$1,SUM(Outputs_Internal!M$4, Outputs_Internal!$M$5),0)*$D31 -> 0 | M31: =$F31*Outputs_Internal!$D$51/12 -> 0 | N31: =$F31*Outputs_Internal!K$51/12 -> 0 | O31: =$F31*Outputs_Internal!L$51/12 -> 0 | P31: =$F31*Outputs_Internal!M$51/12 -> 0 | Q31: =$F31*Outputs_Internal!N$51/12 -> 0 | S31: =IF(MOD(MONTH($B31),3)=0,SUM(H29:H31,M29:M31),0) -> 0 | T31: =IF(MOD(MONTH($B31),3)=0,SUM(I29:I31,N29:N31),0) -> 0 | U31: =IF(MOD(MONTH($B31),3)=0,SUM(J29:J31,O29:O31),0) -> 0 | V31: =IF(MOD(MONTH($B31),3)=0,SUM(K29:K31,P29:P31),0) -> 0 | W31: =IF(MOD(MONTH($B31),3)=0,SUM(L29:L31,Q29:Q31),0) -> 0
B32: =EDATE(B31,1) -> 43800 | D32: =D31*IF(AND(MONTH(B32)=1,YEAR(B32)>=YEAR(Prices!$I$15)),1+Prices!$I$14,1) -> 1.0125 | E32: =IF(B32=Inputs!$C$1,D32,E31) -> 1 | F32: =IF(AND(B32>=Inputs!$C$1,B32<EDATE(Inputs!$C$1,Inputs!$C$2)),E32,0) -> 0 | H32: =IF($B32=Inputs!$C$1,SUM(Outputs_Internal!$D$4, Outputs_Internal!$D$5),0)*$D32 -> 0 | I32: =IF($B32=Inputs!$C$1,SUM(Outputs_Internal!K$4, Outputs_Internal!K$5),0)*$D32 -> 0 | J32: =IF($B32=Inputs!$C$1,SUM(Outputs_Internal!L$4, Outputs_Internal!L$5),0)*$D32 -> 0 | K32: =IF($B32=Inputs!$C$1,SUM(Outputs_Internal!M$4, Outputs_Internal!$M$5),0)*$D32 -> 0 | M32: =$F32*Outputs_Internal!$D$51/12 -> 0 | N32: =$F32*Outputs_Internal!K$51/12 -> 0 | O32: =$F32*Outputs_Internal!L$51/12 -> 0 | P32: =$F32*Outputs_Internal!M$51/12 -> 0 | Q32: =$F32*Outputs_Internal!N$51/12 -> 0 | S32: =IF(MOD(MONTH($B32),3)=0,SUM(H30:H32,M30:M32),0) -> 0 | T32: =IF(MOD(MONTH($B32),3)=0,SUM(I30:I32,N30:N32),0) -> 0 | U32: =IF(MOD(MONTH($B32),3)=0,SUM(J30:J32,O30:O32),0) -> 0 | V32: =IF(MOD(MONTH($B32),3)=0,SUM(K30:K32,P30:P32),0) -> 0 | W32: =IF(MOD(MONTH($B32),3)=0,SUM(L30:L32,Q30:Q32),0) -> 0
... B94: =EDATE(B93,1) -> 45689 | D94: =D93*IF(AND(MONTH(B94)=1,YEAR(B94)>=YEAR(Prices!$I$15)),1+Prices!$I$14,1) -> 1.0908505 | E94: =IF(B94=Inputs!$C$1,D94,E93) -> 1 | F94: =IF(AND(B94>=Inputs!$C$1,B94<EDATE(Inputs!$C$1,Inputs!$C$2)),E94,0) -> 0 | H94: =IF($B94=Inputs!$C$1,SUM(Outputs_Internal!$D$4, Outputs_Internal!$D$5),0)*$D94 -> 0 | I94: =IF($B94=Inputs!$C$1,SUM(Outputs_Internal!K$4, Outputs_Internal!K$5),0)*$D94 -> 0 | J94: =IF($B94=Inputs!$C$1,SUM(Outputs_Internal!L$4, Outputs_Internal!L$5),0)*$D94 -> 0 | K94: =IF($B94=Inputs!$C$1,SUM(Outputs_Internal!M$4, Outputs_Internal!$M$5),0)*$D94 -> 0 | M94: =$F94*Outputs_Internal!$D$51/12 -> 0 | N94: =$F94*Outputs_Internal!K$51/12 -> 0 | O94: =$F94*Outputs_Internal!L$51/12 -> 0 | P94: =$F94*Outputs_Internal!M$51/12 -> 0 | Q94: =$F94*Outputs_Internal!N$51/12 -> 0 | S94: =IF(MOD(MONTH($B94),3)=0,SUM(H92:H94,M92:M94),0) -> 0 | T94: =IF(MOD(MONTH($B94),3)=0,SUM(I92:I94,N92:N94),0) -> 0 | U94: =IF(MOD(MONTH($B94),3)=0,SUM(J92:J94,O92:O94),0) -> 0 | V94: =IF(MOD(MONTH($B94),3)=0,SUM(K92:K94,P92:P94),0) -> 0 | W94: =IF(MOD(MONTH($B94),3)=0,SUM(L92:L94,Q92:Q94),0) -> 0

Sheet Calcs
D2: Data Feed #1 | E2: Data Feed #2 | F2: Data Feed #3 | G2: Data Feed #4 | H2: Data Feed #5 | K2: Product Ranking #1 | L2: Product Ranking #2 | M2: Product Ranking #3 | N2: Product Ranking #4 | O2: Product Ranking #5
B3: One-Time Fees:
C4: Implementation | D4: =IF(AND(Inputs!D5="Y",Inputs!D4="Y"), 0, IF(Inputs!D4="Y", SUM(Prices!$C$3, IF(Inputs!D$6 ="Y", Prices!$C$4, 0)), IF(Inputs!D4="N", Prices!$D$3, 0))) -> 5000 | E4: =IF(AND(Inputs!E5="Y",Inputs!E4="Y"), 0, IF(Inputs!E4="Y", SUM(Prices!$C$3, IF(Inputs!E$6 ="Y", Prices!$C$4, 0)), IF(Inputs!E4="N", Prices!$D$3, 0))) -> 0 | F4: =IF(AND(Inputs!F5="Y",Inputs!F4="Y"), 0, IF(Inputs!F4="Y", SUM(Prices!$C$3, IF(Inputs!F$6 ="Y", Prices!$C$4, 0)), IF(Inputs!F4="N", Prices!$D$3, 0))) -> 0 | G4: =IF(AND(Inputs!G5="Y",Inputs!G4="Y"), 0, IF(Inputs!G4="Y", SUM(Prices!$C$3, IF(Inputs!G$6 ="Y", Prices!$C$4, 0)), IF(Inputs!G4="N", Prices!$D$3, 0))) -> 0 | H4: =IF(AND(Inputs!H5="Y",Inputs!H4="Y"), 0, IF(Inputs!H4="Y", SUM(Prices!$C$3, IF(Inputs!H$6 ="Y", Prices!$C$4, 0)), IF(Inputs!H4="N", Prices!$D$3, 0))) -> 0
B6: Patients Above 25,000 (Non-CCLF Only) | D6: =IF(Inputs!D4="N",MAX(Inputs!D7-25000,0),0) -> 0 | E6: =IF(Inputs!E4="N",MAX(Inputs!E7-25000,0),) -> 0 | F6: =IF(Inputs!F4="N",MAX(Inputs!F7-25000,0),) -> 0 | G6: =IF(Inputs!G4="N",MAX(Inputs!G7-25000,0),) -> 0 | H6: =IF(Inputs!H4="N",MAX(Inputs!H7-25000,0),) -> 0
B8: Annual Base Data Fees (With Implicit forces):
C9: Base Processing Fee | D9: =IF(Inputs!D4="Y", Prices!$C$6, IF(Inputs!D4="N", Prices!$D$6, 0)) -> 18000 | E9: =IF(Inputs!E4="Y", Prices!$C$6, IF(Inputs!E4="N", Prices!$D$6, 0)) -> 0 | F9: =IF(Inputs!F4="Y", Prices!$C$6, IF(Inputs!F4="N", Prices!$D$6, 0)) -> 0 | G9: =IF(Inputs!G4="Y", Prices!$C$6, IF(Inputs!G4="N", Prices!$D$6, 0)) -> 0 | H9: =IF(Inputs!H4="Y", Prices!$C$6, IF(Inputs!H4="N", Prices!$D$6, 0)) -> 0
C10: Datamart Fee | D10: =IF(Inputs!D8="Y", Prices!$C$7, 0) -> 8100 | E10: =IF(Inputs!E8="Y", Prices!$C$7, 0) -> 0 | F10: =IF(Inputs!F8="Y", Prices!$C$7, 0) -> 0 | G10: =IF(Inputs!G8="Y", Prices!$C$7, 0) -> 0 | H10: =IF(Inputs!H8="Y", Prices!$C$7, 0) -> 0
C11: HCC Risk Scores | D11: =IF(OR(Inputs!D9="Y",Inputs!D$19="Y"), Prices!$C10, 0) -> 1200 | E11: =IF(OR(Inputs!E9="Y",Inputs!E$19="Y"), Prices!$C10, 0) -> 0 | F11: =IF(OR(Inputs!F9="Y",Inputs!F$19="Y"), Prices!$C10, 0) -> 0 | G11: =IF(OR(Inputs!G9="Y",Inputs!G$19="Y"), Prices!$C10, 0) -> 0 | H11: =IF(OR(Inputs!H9="Y",Inputs!H$19="Y"), Prices!$C10, 0) -> 0
C12: HCG Benchmarks | D12: =IF(OR(Inputs!D10="Y",Inputs!D$19="Y"), Prices!$C11, 0) -> 4800 | E12: =IF(OR(Inputs!E10="Y",Inputs!E$19="Y"), Prices!$C11, 0) -> 0 | F12: =IF(OR(Inputs!F10="Y",Inputs!F$19="Y"), Prices!$C11, 0) -> 0 | G12: =IF(OR(Inputs!G10="Y",Inputs!G$19="Y"), Prices!$C11, 0) -> 0 | H12: =IF(OR(Inputs!H10="Y",Inputs!H$19="Y"), Prices!$C11, 0) -> 0
C13: PAC/Grouping/Benchmarks | D13: =IF(OR(Inputs!D11="Y",Inputs!D$19="Y"), Prices!$C12, 0) -> 2400 | E13: =IF(OR(Inputs!E11="Y",Inputs!E$19="Y"), Prices!$C12, 0) -> 0 | F13: =IF(OR(Inputs!F11="Y",Inputs!F$19="Y"), Prices!$C12, 0) -> 0 | G13: =IF(OR(Inputs!G11="Y",Inputs!G$19="Y"), Prices!$C12, 0) -> 0 | H13: =IF(OR(Inputs!H11="Y",Inputs!H$19="Y"), Prices!$C12, 0) -> 0
C14: Key Claims Metrics | D14: =IF(OR(Inputs!D12="Y",Inputs!D$19="Y"), Prices!$C13, 0) -> 2400 | E14: =IF(OR(Inputs!E12="Y",Inputs!E$19="Y"), Prices!$C13, 0) -> 0 | F14: =IF(OR(Inputs!F12="Y",Inputs!F$19="Y"), Prices!$C13, 0) -> 0 | G14: =IF(OR(Inputs!G12="Y",Inputs!G$19="Y"), Prices!$C13, 0) -> 0 | H14: =IF(OR(Inputs!H12="Y",Inputs!H$19="Y"), Prices!$C13, 0) -> 0
C15: Waste Calculator | D15: =IF(OR(Inputs!D13="Y",Inputs!D$19="Y"), Prices!$C14, 0) -> 7200 | E15: =IF(OR(Inputs!E13="Y",Inputs!E$19="Y"), Prices!$C14, 0) -> 0 | F15: =IF(OR(Inputs!F13="Y",Inputs!F$19="Y"), Prices!$C14, 0) -> 0 | G15: =IF(OR(Inputs!G13="Y",Inputs!G$19="Y"), Prices!$C14, 0) -> 0 | H15: =IF(OR(Inputs!H13="Y",Inputs!H$19="Y"), Prices!$C14, 0) -> 0
C16: Medical Conditions | D16: =IF(OR(Inputs!D14="Y",Inputs!D$19="Y"), Prices!$C15, 0) -> 4800 | E16: =IF(OR(Inputs!E14="Y",Inputs!E$19="Y"), Prices!$C15, 0) -> 0 | F16: =IF(OR(Inputs!F14="Y",Inputs!F$19="Y"), Prices!$C15, 0) -> 0 | G16: =IF(OR(Inputs!G14="Y",Inputs!G$19="Y"), Prices!$C15, 0) -> 0 | H16: =IF(OR(Inputs!H14="Y",Inputs!H$19="Y"), Prices!$C15, 0) -> 0
C17: PRM Oppourtunity Prospective Scores | D17: =IF(OR(Inputs!D15="Y",Inputs!D$20="Y"), Prices!$C16, 0) -> 0 | E17: =IF(OR(Inputs!E15="Y",Inputs!E$20="Y"), Prices!$C16, 0) -> 0 | F17: =IF(OR(Inputs!F15="Y",Inputs!F$20="Y"), Prices!$C16, 0) -> 0 | G17: =IF(OR(Inputs!G15="Y",Inputs!G$20="Y"), Prices!$C16, 0) -> 0 | H17: =IF(OR(Inputs!H15="Y",Inputs!H$20="Y"), Prices!$C16, 0) -> 0
C18: PRM Conditions to Consider | D18: =IF(OR(Inputs!D16="Y",Inputs!D$20="Y"), Prices!$C17, 0) -> 0 | E18: =IF(OR(Inputs!E16="Y",Inputs!E$20="Y"), Prices!$C17, 0) -> 0 | F18: =IF(OR(Inputs!F16="Y",Inputs!F$20="Y"), Prices!$C17, 0) -> 0 | G18: =IF(OR(Inputs!G16="Y",Inputs!G$20="Y"), Prices!$C17, 0) -> 0 | H18: =IF(OR(Inputs!H16="Y",Inputs!H$20="Y"), Prices!$C17, 0) -> 0
C19: PRM Medicare ACO Analytics (CCLF Only) | D19: =IF(OR(Inputs!D17="Y",Inputs!D$20="Y"), Prices!$C18, 0) -> 0 | E19: =IF(OR(Inputs!E17="Y",Inputs!E$20="Y"), Prices!$C18, 0) -> 0 | F19: =IF(OR(Inputs!F17="Y",Inputs!F$20="Y"), Prices!$C18, 0) -> 0 | G19: =IF(OR(Inputs!G17="Y",Inputs!G$20="Y"), Prices!$C18, 0) -> 0 | H19: =IF(OR(Inputs!H17="Y",Inputs!H$20="Y"), Prices!$C18, 0) -> 0
B21: Annual PMPM Add-On Data Fees (With implicit forces):
C22: Base Processing Fee | D22: =IF(Inputs!D$4="Y", 0, IF(D$6 = "", "", PRODUCT(D$6, Prices!$E$6))) -> 0 | E22: =IF(Inputs!E$4="Y", 0, IF(E$6 = "", "", PRODUCT(E$6, Prices!$E$6))) -> 0 | F22: =IF(Inputs!F$4="Y", 0, IF(F$6 = "", "", PRODUCT(F$6, Prices!$E$6))) -> 0 | G22: =IF(Inputs!G$4="Y", 0, IF(G$6 = "", "", PRODUCT(G$6, Prices!$E$6))) -> 0 | H22: =IF(Inputs!H$4="Y", 0, IF(H$6 = "", "", PRODUCT(H$6, Prices!$E$6))) -> 0
C23: Datamart Fee | D23: 0 | E23: 0 | F23: 0 | G23: 0 | H23: 0
C24: HCC Risk Scores | D24: =IF(OR(Inputs!D$4="Y", D$6 = 0), 0, IF(OR(Inputs!D9="Y",Inputs!D$19="Y"),PRODUCT(D$6, Prices!$D10),0)) -> 0 | E24: =IF(OR(Inputs!E$4="Y", E$6 = 0), 0, IF(OR(Inputs!E9="Y",Inputs!E$19="Y"),PRODUCT(E$6, Prices!$D10),0)) -> 0 | F24: =IF(OR(Inputs!F$4="Y", F$6 = 0), 0, IF(OR(Inputs!F9="Y",Inputs!F$19="Y"),PRODUCT(F$6, Prices!$D10),0)) -> 0 | G24: =IF(OR(Inputs!G$4="Y", G$6 = 0), 0, IF(OR(Inputs!G9="Y",Inputs!G$19="Y"),PRODUCT(G$6, Prices!$D10),0)) -> 0 | H24: =IF(OR(Inputs!H$4="Y", H$6 = 0), 0, IF(OR(Inputs!H9="Y",Inputs!H$19="Y"),PRODUCT(H$6, Prices!$D10),0)) -> 0
C25: HCG Benchmarks | D25: =IF(OR(Inputs!D$4="Y", D$6 = 0), 0, IF(OR(Inputs!D10="Y",Inputs!D$19="Y"),PRODUCT(D$6, Prices!$D11),0)) -> 0 | E25: =IF(OR(Inputs!E$4="Y", E$6 = 0), 0, IF(OR(Inputs!E10="Y",Inputs!E$19="Y"),PRODUCT(E$6, Prices!$D11),0)) -> 0 | F25: =IF(OR(Inputs!F$4="Y", F$6 = 0), 0, IF(OR(Inputs!F10="Y",Inputs!F$19="Y"),PRODUCT(F$6, Prices!$D11),0)) -> 0 | G25: =IF(OR(Inputs!G$4="Y", G$6 = 0), 0, IF(OR(Inputs!G10="Y",Inputs!G$19="Y"),PRODUCT(G$6, Prices!$D11),0)) -> 0 | H25: =IF(OR(Inputs!H$4="Y", H$6 = 0), 0, IF(OR(Inputs!H10="Y",Inputs!H$19="Y"),PRODUCT(H$6, Prices!$D11),0)) -> 0
C26: PAC/Grouping/Benchmarks | D26: =IF(OR(Inputs!D$4="Y", D$6 = 0), 0, IF(OR(Inputs!D11="Y",Inputs!D$19="Y"),PRODUCT(D$6, Prices!$D12),0)) -> 0 | E26: =IF(OR(Inputs!E$4="Y", E$6 = 0), 0, IF(OR(Inputs!E11="Y",Inputs!E$19="Y"),PRODUCT(E$6, Prices!$D12),0)) -> 0 | F26: =IF(OR(Inputs!F$4="Y", F$6 = 0), 0, IF(OR(Inputs!F11="Y",Inputs!F$19="Y"),PRODUCT(F$6, Prices!$D12),0)) -> 0 | G26: =IF(OR(Inputs!G$4="Y", G$6 = 0), 0, IF(OR(Inputs!G11="Y",Inputs!G$19="Y"),PRODUCT(G$6, Prices!$D12),0)) -> 0 | H26: =IF(OR(Inputs!H$4="Y", H$6 = 0), 0, IF(OR(Inputs!H11="Y",Inputs!H$19="Y"),PRODUCT(H$6, Prices!$D12),0)) -> 0
C27: Key Claims Metrics | D27: =IF(OR(Inputs!D$4="Y", D$6 = 0), 0, IF(OR(Inputs!D12="Y",Inputs!D$19="Y"),PRODUCT(D$6, Prices!$D13),0)) -> 0 | E27: =IF(OR(Inputs!E$4="Y", E$6 = 0), 0, IF(OR(Inputs!E12="Y",Inputs!E$19="Y"),PRODUCT(E$6, Prices!$D13),0)) -> 0 | F27: =IF(OR(Inputs!F$4="Y", F$6 = 0), 0, IF(OR(Inputs!F12="Y",Inputs!F$19="Y"),PRODUCT(F$6, Prices!$D13),0)) -> 0 | G27: =IF(OR(Inputs!G$4="Y", G$6 = 0), 0, IF(OR(Inputs!G12="Y",Inputs!G$19="Y"),PRODUCT(G$6, Prices!$D13),0)) -> 0 | H27: =IF(OR(Inputs!H$4="Y", H$6 = 0), 0, IF(OR(Inputs!H12="Y",Inputs!H$19="Y"),PRODUCT(H$6, Prices!$D13),0)) -> 0
C28: Waste Calculator | D28: =IF(OR(Inputs!D$4="Y", D$6 = 0), 0, IF(OR(Inputs!D13="Y",Inputs!D$19="Y"),PRODUCT(D$6, Prices!$D14),0)) -> 0 | E28: =IF(OR(Inputs!E$4="Y", E$6 = 0), 0, IF(OR(Inputs!E13="Y",Inputs!E$19="Y"),PRODUCT(E$6, Prices!$D14),0)) -> 0 | F28: =IF(OR(Inputs!F$4="Y", F$6 = 0), 0, IF(OR(Inputs!F13="Y",Inputs!F$19="Y"),PRODUCT(F$6, Prices!$D14),0)) -> 0 | G28: =IF(OR(Inputs!G$4="Y", G$6 = 0), 0, IF(OR(Inputs!G13="Y",Inputs!G$19="Y"),PRODUCT(G$6, Prices!$D14),0)) -> 0 | H28: =IF(OR(Inputs!H$4="Y", H$6 = 0), 0, IF(OR(Inputs!H13="Y",Inputs!H$19="Y"),PRODUCT(H$6, Prices!$D14),0)) -> 0
C29: Medical Conditions | D29: =IF(OR(Inputs!D$4="Y", D$6 = 0), 0, IF(OR(Inputs!D14="Y",Inputs!D$19="Y"),PRODUCT(D$6, Prices!$D15),0)) -> 0 | E29: =IF(OR(Inputs!E$4="Y", E$6 = 0), 0, IF(OR(Inputs!E14="Y",Inputs!E$19="Y"),PRODUCT(E$6, Prices!$D15),0)) -> 0 | F29: =IF(OR(Inputs!F$4="Y", F$6 = 0), 0, IF(OR(Inputs!F14="Y",Inputs!F$19="Y"),PRODUCT(F$6, Prices!$D15),0)) -> 0 | G29: =IF(OR(Inputs!G$4="Y", G$6 = 0), 0, IF(OR(Inputs!G14="Y",Inputs!G$19="Y"),PRODUCT(G$6, Prices!$D15),0)) -> 0 | H29: =IF(OR(Inputs!H$4="Y", H$6 = 0), 0, IF(OR(Inputs!H14="Y",Inputs!H$19="Y"),PRODUCT(H$6, Prices!$D15),0)) -> 0
C30: PRM Oppourtunity Prospective Scores | D30: =IF(OR(Inputs!D$4="Y", D$6 = 0), 0, IF(OR(Inputs!D15="Y",Inputs!D$20="Y"),PRODUCT(D$6, Prices!$D16),0)) -> 0 | E30: =IF(OR(Inputs!E$4="Y", E$6 = 0), 0, IF(OR(Inputs!E15="Y",Inputs!E$20="Y"),PRODUCT(E$6, Prices!$D16),0)) -> 0 | F30: =IF(OR(Inputs!F$4="Y", F$6 = 0), 0, IF(OR(Inputs!F15="Y",Inputs!F$20="Y"),PRODUCT(F$6, Prices!$D16),0)) -> 0 | G30: =IF(OR(Inputs!G$4="Y", G$6 = 0), 0, IF(OR(Inputs!G15="Y",Inputs!G$20="Y"),PRODUCT(G$6, Prices!$D16),0)) -> 0 | H30: =IF(OR(Inputs!H$4="Y", H$6 = 0), 0, IF(OR(Inputs!H15="Y",Inputs!H$20="Y"),PRODUCT(H$6, Prices!$D16),0)) -> 0
