Workbook
Name ACOInsight1: Inputs!$D$18:$D$19

Sheet Inputs
B1: Month Contract Starts | C1: 43101
B2: Contract Months | C2: 18
D3: Data Feed #1 | E3: Data Feed #2 | F3: Data Feed #3 | G3: Data Feed #4 | H3: Data Feed #5
B4: CCLF | D4: Y | L4: Y
B5: Collaborative Member | D5: Y | L5: N
B6: Non-CMS Files | D6: N
B7: Initial Estimated Lives | D7: 50000
B8: Basic Datamart | D8: Y
B9: HCC Risk Scores | D9: Y
B10: HCG Benchmarks | D10: Y
B11: PAC/Grouping/Benchmarks | D11: Y
B12: Key Claims Metrics | D12: Y
B13: Waste Calculator | D13: Y
B14: Medical Conditions | D14: Y
B15: PRM Oppourtunity Prospective Scores | D15: N
B16: PRM Conditions to Consider | D16: N
B17: PRM Medicare ACO Analytics | D17: N
B18: ACO Insight - Basic | D18: N
B19: ACO Insight - Enhanced | D19: Y
... B21: PRM Physician Risk and Credibility Adjusted Report | D21: N

Sheet Outputs_External
D2: Data Feed #1 | E2: Data Feed #2 | F2: Data Feed #3 | G2: Data Feed #4 | H2: Data Feed #5
B3: One-Time Fees:
C4: Implementation | D4: =MAX(Calcs!D4, 0) -> 0 | E4: =MAX(Calcs!E4, 0) -> 0 | F4: =MAX(Calcs!F4, 0) -> 0 | G4: =MAX(Calcs!G4, 0) -> 0 | H4: =MAX(Calcs!H4, 0) -> 0
B6: Annual Data Fees:
C7: Base Processing Fee | D7: =SUM(Calcs!D35, Calcs!D48) -> 15000 | E7: =SUM(Calcs!E35, Calcs!E48) -> 0 | F7: =SUM(Calcs!F35, Calcs!F48) -> 0 | G7: =SUM(Calcs!G35, Calcs!G48) -> 0 | H7: =SUM(Calcs!H35, Calcs!H48) -> 0
C8: Datamart Fee | D8: =SUM(Calcs!D36, Calcs!D49) -> 6750 | E8: =SUM(Calcs!E36, Calcs!E49) -> 0 | F8: =SUM(Calcs!F36, Calcs!F49) -> 0 | G8: =SUM(Calcs!G36, Calcs!G49) -> 0 | H8: =SUM(Calcs!H36, Calcs!H49) -> 0
C9: HCC Risk Scores | D9: =SUM(Calcs!D37, Calcs!D50) -> 0 | E9: =SUM(Calcs!E37, Calcs!E50) -> 0 | F9: =SUM(Calcs!F37, Calcs!F50) -> 0 | G9: =SUM(Calcs!G37, Calcs!G50) -> 0 | H9: =SUM(Calcs!H37, Calcs!H50) -> 0
C10: HCG Benchmarks | D10: =SUM(Calcs!D38, Calcs!D51) -> 0 | E10: =SUM(Calcs!E38, Calcs!E51) -> 0 | F10: =SUM(Calcs!F38, Calcs!F51) -> 0 | G10: =SUM(Calcs!G38, Calcs!G51) -> 0 | H10: =SUM(Calcs!H38, Calcs!H51) -> 0
C11: PAC/Grouping/Benchmarks | D11: =SUM(Calcs!D39, Calcs!D52) -> 0 | E11: =SUM(Calcs!E39, Calcs!E52) -> 0 | F11: =SUM(Calcs!F39, Calcs!F52) -> 0 | G11: =SUM(Calcs!G39, Calcs!G52) -> 0 | H11: =SUM(Calcs!H39, Calcs!H52) -> 0
C12: Key Claims Metrics | D12: =SUM(Calcs!D40, Calcs!D53) -> 0 | E12: =SUM(Calcs!E40, Calcs!E53) -> 0 | F12: =SUM(Calcs!F40, Calcs!F53) -> 0 | G12: =SUM(Calcs!G40, Calcs!G53) -> 0 | H12: =SUM(Calcs!H40, Calcs!H53) -> 0
C13: Waste Calculator | D13: =SUM(Calcs!D41, Calcs!D54) -> 0 | E13: =SUM(Calcs!E41, Calcs!E54) -> 0 | F13: =SUM(Calcs!F41, Calcs!F54) -> 0 | G13: =SUM(Calcs!G41, Calcs!G54) -> 0 | H13: =SUM(Calcs!H41, Calcs!H54) -> 0
C14: Medical Conditions | D14: =SUM(Calcs!D42, Calcs!D55) -> 0 | E14: =SUM(Calcs!E42, Calcs!E55) -> 0 | F14: =SUM(Calcs!F42, Calcs!F55) -> 0 | G14: =SUM(Calcs!G42, Calcs!G55) -> 0 | H14: =SUM(Calcs!H42, Calcs!H55) -> 0
C15: PRM Oppourtunity Prospective Scores | D15: =SUM(Calcs!D43, Calcs!D56) -> 0 | E15: =SUM(Calcs!E43, Calcs!E56) -> 0 | F15: =SUM(Calcs!F43, Calcs!F56) -> 0 | G15: =SUM(Calcs!G43, Calcs!G56) -> 0 | H15: =SUM(Calcs!H43, Calcs!H56) -> 0
C16: PRM Conditions to Consider | D16: =SUM(Calcs!D44, Calcs!D57) -> 0 | E16: =SUM(Calcs!E44, Calcs!E57) -> 0 | F16: =SUM(Calcs!F44, Calcs!F57) -> 0 | G16: =SUM(Calcs!G44, Calcs!G57) -> 0 | H16: =SUM(Calcs!H44, Calcs!H57) -> 0
C17: PRM Medicare ACO Analytics (CCLF Only) | D17: =SUM(Calcs!D45, Calcs!D58) -> 0 | E17: =SUM(Calcs!E45, Calcs!E58) -> 0 | F17: =SUM(Calcs!F45, Calcs!F58) -> 0 | G17: =SUM(Calcs!G45, Calcs!G58) -> 0 | H17: =SUM(Calcs!H45, Calcs!H58) -> 0
B19: Annual Product Fees
C20: ACO Insight - Basic | D20: =SUM(Calcs!D61, Calcs!D67) -> 0 | E20: =SUM(Calcs!E61, Calcs!E67) -> 0 | F20: =SUM(Calcs!F61, Calcs!F67) -> 0 | G20: =SUM(Calcs!G61, Calcs!G67) -> 0 | H20: =SUM(Calcs!H61, Calcs!H67) -> 0
C21: ACO Insight - Enhanced | D21: =SUM(Calcs!D62, Calcs!D68) -> 33000 | E21: =SUM(Calcs!E62, Calcs!E68) -> 0 | F21: =SUM(Calcs!F62, Calcs!F68) -> 0 | G21: =SUM(Calcs!G62, Calcs!G68) -> 0 | H21: =SUM(Calcs!H62, Calcs!H68) -> 0
C22: PRM Care Coordinator Report | D22: =SUM(Calcs!D63, Calcs!D69) -> 0 | E22: =SUM(Calcs!E63, Calcs!E69) -> 0 | F22: =SUM(Calcs!F63, Calcs!F69) -> 0 | G22: =SUM(Calcs!G63, Calcs!G69) -> 0 | H22: =SUM(Calcs!H63, Calcs!H69) -> 0
C23: PRM Physician Risk and Credibility Adjusted Report | D23: =SUM(Calcs!D64, Calcs!D70) -> 0 | E23: =SUM(Calcs!E64, Calcs!E70) -> 0 | F23: =SUM(Calcs!F64, Calcs!F70) -> 0 | G23: =SUM(Calcs!G64, Calcs!G70) -> 0 | H23: =SUM(Calcs!H64, Calcs!H70) -> 0
B25: Discounts
C26: Product Discounts | D26: =SUM(Calcs!D85:D86) -> 0 | E26: =SUM(Calcs!E85:E86) -> 0 | F26: =SUM(Calcs!F85:F86) -> 0 | G26: =SUM(Calcs!G85:G86) -> 0 | H26: =SUM(Calcs!H85:H86) -> 0
C27: Datafeed Discounts | D27: =Calcs!D90 -> 0 | E27: =Calcs!E90 -> 0 | F27: =Calcs!F90 -> 0 | G27: =Calcs!G90 -> 0 | H27: =Calcs!H90 -> 0
C28: Existing Collaborative Discount | D28: =Calcs!D92 -> -3525 | E28: =Calcs!E92 -> 0 | F28: =Calcs!F92 -> 0 | G28: =Calcs!G92 -> 0 | H28: =Calcs!H92 -> 0
B30: Annual Total | D30: =SUM(D7:D17, D20:D23, D26:D28) -> 51225 | E30: =SUM(E7:E17, E20:E23, E26:E28) -> 0 | F30: =SUM(F7:F17, F20:F23, F26:F28) -> 0 | G30: =SUM(G7:G17, G20:G23, G26:G28) -> 0 | H30: =SUM(H7:H17, H20:H23, H26:H28) -> 0
B32: Price inflation multiplier
C33: =INDEX(Outputs_Timeline!$D$3:$D$94,MATCH(Inputs!$C$1,Outputs_Timeline!$B$3:$B$94,0),1) -> 1
B35: Prorated Total with Implementation | D35: =(D30/12*Inputs!$C$2+D4)*$C$33 -> 76837.5 | E35: =(E30/12*Inputs!$C$2+E4)*$C$33 -> 0 | F35: =(F30/12*Inputs!$C$2+F4)*$C$33 -> 0 | G35: =(G30/12*Inputs!$C$2+G4)*$C$33 -> 0 | H35: =(H30/12*Inputs!$C$2+H4)*$C$33 -> 0
B38: Total across entire contract duration
C39: =SUM(Outputs_Timeline!S:S) -> 76837.5
C40: =SUM(D35:H35) -> 76837.5

Sheet Outputs_Internal
F1: Revenue Split Percentages
D2: Totals | F2: New York | G2: PRM | H2: MI Royalties | I2: Other Royalties | K2: New York | L2: PRM | M2: MI Royalties | N2: Other Royalties
B3: One-Time Fees:
C4: Implementation (CCLF) | D4: =SUMIF(Inputs!$D$4:$H$4, "Y", Outputs_External!D4:'Outputs_External'!H4) -> 0 | F4: 0.5 | G4: 0.5 | H4: =1-SUM(F4:G4) -> 0 | K4: =F4*$D4 -> 0 | L4: =G4*$D4 -> 0 | M4: =H4*$D4 -> 0 | N4: =I4*$D4 -> 0
C5: Implementation (non-CCLF) | D5: =SUMIF(Inputs!$D$4:$H$4, "N", Outputs_External!D4:'Outputs_External'!H4) -> 0 | F5: 0.1 | G5: 0.9 | H5: =1-SUM(F5:G5) -> 0 | K5: =F5*$D5 -> 0 | L5: =G5*$D5 -> 0 | M5: =H5*$D5 -> 0 | N5: =I5*$D5 -> 0
B7: Annual Base Data Fees (with implicit forces):
C8: Base Processing Fee | D8: =SUM(Calcs!D9:H9) -> 15000 | F8: 0.4 | G8: 0.6 | H8: =1-SUM(F8:G8) -> 0 | I8: 0 | K8: =F8*$D8 -> 6000 | L8: =G8*$D8 -> 9000 | M8: =H8*$D8 -> 0 | N8: =I8*$D8 -> 0
C9: Datamart Fee | D9: =SUM(Calcs!D10:H10) -> 6750 | F9: 0.2 | G9: 0.8 | H9: =1-SUM(F9:G9) -> 0 | I9: 0 | K9: =F9*$D9 -> 1350 | L9: =G9*$D9 -> 5400 | M9: =H9*$D9 -> 0 | N9: =I9*$D9 -> 0
C10: HCC Risk Scores | D10: =SUM(Calcs!D11:H11) -> 1000 | F10: 0.1 | G10: 0.9 | H10: =1-SUM(F10:G10) -> 0 | I10: 0 | K10: =F10*$D10 -> 100 | L10: =G10*$D10 -> 900 | M10: =H10*$D10 -> 0 | N10: =I10*$D10 -> 0
C11: HCG Benchmarks | D11: =SUM(Calcs!D12:H12) -> 4000 | F11: 0.45 | G11: 0.45 | H11: 0 | I11: 0.1 | K11: =F11*$D11 -> 1800 | L11: =G11*$D11 -> 1800 | M11: =H11*$D11 -> 0 | N11: =I11*$D11 -> 400
C12: PAC/Grouping/Benchmarks | D12: =SUM(Calcs!D13:H13) -> 2000 | F12: 0.9 | G12: 0.1 | H12: =1-SUM(F12:G12) -> 0 | I12: 0 | K12: =F12*$D12 -> 1800 | L12: =G12*$D12 -> 200 | M12: =H12*$D12 -> 0 | N12: =I12*$D12 -> 0
C13: Key Claims Metrics | D13: =SUM(Calcs!D14:H14) -> 2000 | F13: 0.1 | G13: 0.9 | H13: =1-SUM(F13:G13) -> 0 | I13: 0 | K13: =F13*$D13 -> 200 | L13: =G13*$D13 -> 1800 | M13: =H13*$D13 -> 0 | N13: =I13*$D13 -> 0
C14: Waste Calculator | D14: =SUM(Calcs!D15:H15) -> 6000 | F14: 0.1 | G14: 0.1 | H14: 0.8 | I14: 0 | K14: =F14*$D14 -> 600 | L14: =G14*$D14 -> 600 | M14: =H14*$D14 -> 4800 | N14: =I14*$D14 -> 0
C15: Medical Conditions | D15: =SUM(Calcs!D16:H16) -> 4000 | F15: 0.6 | G15: 0.4 | H15: =1-SUM(F15:G15) -> 0 | I15: 0 | K15: =F15*$D15 -> 2400 | L15: =G15*$D15 -> 1600 | M15: =H15*$D15 -> 0 | N15: =I15*$D15 -> 0
C16: PRM Oppourtunity Prospective Scores | D16: =SUM(Calcs!D17:H17) -> 0 | F16: 0.1 | G16: 0.9 | H16: =1-SUM(F16:G16) -> 0 | I16: 0 | K16: =F16*$D16 -> 0 | L16: =G16*$D16 -> 0 | M16: =H16*$D16 -> 0 | N16: =I16*$D16 -> 0
C17: PRM Conditions to Consider | D17: =SUM(Calcs!D18:H18) -> 0 | F17: 0.1 | G17: 0.9 | H17: =1-SUM(F17:G17) -> 0 | I17: 0 | K17: =F17*$D17 -> 0 | L17: =G17*$D17 -> 0 | M17: =H17*$D17 -> 0 | N17: =I17*$D17 -> 0
C18: PRM Medicare ACO Analytics (CCLF Only) | D18: =SUM(Calcs!D19:H19) -> 0 | F18: 0.1 | G18: 0.9 | H18: =1-SUM(F18:G18) -> 0 | I18: 0 | K18: =F18*$D18 -> 0 | L18: =G18*$D18 -> 0 | M18: =H18*$D18 -> 0 | N18: =I18*$D18 -> 0
G20: PRM Increase on PMPM Add-on fees: | H20: 0.1
B22: Annual PMPM Add-on Data Fees (with implicit forces):
C23: Base Processing Fee | D23: =SUM(Calcs!D22:H22) -> 0 | F23: =(1-G23)*F8/SUM(F8,H8) -> 0.3 | G23: =MIN(1,G8+$H$20) -> 0.7 | H23: =IF(H8=0, 0,(1-G23)*H8/SUM(F8,H8)) -> 0 | I23: =IF(I8=0, 0,(1-G23)*I8/SUM(F8,I8)) -> 0 | K23: =F23*$D23 -> 0 | L23: =G23*$D23 -> 0 | M23: =H23*$D23 -> 0 | N23: =I23*$D23 -> 0
C24: Datamart Fee | D24: =SUM(Calcs!D23:H23) -> 0 | F24: =(1-G24)*F9/SUM(F9,H9) -> 0.1 | G24: =MIN(1,G9+$H$20) -> 0.9 | H24: =IF(H9=0, 0,(1-G24)*H9/SUM(F9,H9)) -> 0 | I24: =IF(I9=0, 0,(1-G24)*I9/SUM(F9,I9)) -> 0 | K24: =F24*$D24 -> 0 | L24: =G24*$D24 -> 0 | M24: =H24*$D24 -> 0 | N24: =I24*$D24 -> 0
C25: HCC Risk Scores | D25: =SUM(Calcs!D24:H24) -> 0 | F25: =(1-G25)*F10/SUM(F10,H10) -> 0 | G25: =MIN(1,G10+$H$20) -> 1 | H25: =IF(H10=0, 0,(1-G25)*H10/SUM(F10,H10)) -> 0 | I25: =IF(I10=0, 0,(1-G25)*I10/SUM(F10,I10)) -> 0 | K25: =F25*$D25 -> 0 | L25: =G25*$D25 -> 0 | M25: =H25*$D25 -> 0 | N25: =I25*$D25 -> 0
C26: HCG Benchmarks | D26: =SUM(Calcs!D25:H25) -> 0 | F26: =(1-G26)*F11/SUM(F11,H11, I11) -> 0.36818182 | G26: =MIN(1,G11+$H$20) -> 0.55 | H26: =IF(H11=0, 0,(1-G26)*H11/SUM(F11,H11)) -> 0 | I26: =IF(I11=0, 0,(1-G26)*I11/SUM(F11,I11)) -> 0.081818182 | K26: =F26*$D26 -> 0 | L26: =G26*$D26 -> 0 | M26: =H26*$D26 -> 0 | N26: =I26*$D26 -> 0
C27: PAC/Grouping/Benchmarks | D27: =SUM(Calcs!D26:H26) -> 0 | F27: =(1-G27)*F12/SUM(F12,H12) -> 0.8 | G27: =MIN(1,G12+$H$20) -> 0.2 | H27: =IF(H12=0, 0,(1-G27)*H12/SUM(F12,H12)) -> 0 | I27: =IF(I12=0, 0,(1-G27)*I12/SUM(F12,I12)) -> 0 | K27: =F27*$D27 -> 0 | L27: =G27*$D27 -> 0 | M27: =H27*$D27 -> 0 | N27: =I27*$D27 -> 0
C28: Key Claims Metrics | D28: =SUM(Calcs!D27:H27) -> 0 | F28: =(1-G28)*F13/SUM(F13,H13) -> 0 | G28: =MIN(1,G13+$H$20) -> 1 | H28: =IF(H13=0, 0,(1-G28)*H13/SUM(F13,H13)) -> 0 | I28: =IF(I13=0, 0,(1-G28)*I13/SUM(F13,I13)) -> 0 | K28: =F28*$D28 -> 0 | L28: =G28*$D28 -> 0 | M28: =H28*$D28 -> 0 | N28: =I28*$D28 -> 0
C29: Waste Calculator | D29: =SUM(Calcs!D28:H28) -> 0 | F29: =(1-G29)*F14/SUM(F14,H14) -> 0.088888889 | G29: =MIN(1,G14+$H$20) -> 0.2 | H29: =IF(H14=0, 0,(1-G29)*H14/SUM(F14,H14)) -> 0.71111111 | I29: =IF(I14=0, 0,(1-G29)*I14/SUM(F14,I14)) -> 0 | K29: =F29*$D29 -> 0 | L29: =G29*$D29 -> 0 | M29: =H29*$D29 -> 0 | N29: =I29*$D29 -> 0
C30: Medical Conditions | D30: =SUM(Calcs!D29:H29) -> 0 | F30: =(1-G30)*F15/SUM(F15,H15) -> 0.5 | G30: =MIN(1,G15+$H$20) -> 0.5 | H30: =IF(H15=0, 0,(1-G30)*H15/SUM(F15,H15)) -> 0 | I30: =IF(I15=0, 0,(1-G30)*I15/SUM(F15,I15)) -> 0 | K30: =F30*$D30 -> 0 | L30: =G30*$D30 -> 0 | M30: =H30*$D30 -> 0 | N30: =I30*$D30 -> 0
C31: PRM Oppourtunity Prospective Scores | D31: =SUM(Calcs!D30:H30) -> 0 | F31: =(1-G31)*F16/SUM(F16,H16) -> 0 | G31: =MIN(1,G16+$H$20) -> 1 | H31: =IF(H16=0, 0,(1-G31)*H16/SUM(F16,H16)) -> 0 | I31: =IF(I16=0, 0,(1-G31)*I16/SUM(F16,I16)) -> 0 | K31: =F31*$D31 -> 0 | L31: =G31*$D31 -> 0 | M31: =H31*$D31 -> 0 | N31: =I31*$D31 -> 0
C32: PRM Conditions to Consider | D32: =SUM(Calcs!D31:H31) -> 0 | F32: =(1-G32)*F17/SUM(F17,H17) -> 0 | G32: =MIN(1,G17+$H$20) -> 1 | H32: =IF(H17=0, 0,(1-G32)*H17/SUM(F17,H17)) -> 0 | I32: =IF(I17=0, 0,(1-G32)*I17/SUM(F17,I17)) -> 0 | K32: =F32*$D32 -> 0 | L32: =G32*$D32 -> 0 | M32: =H32*$D32 -> 0 | N32: =I32*$D32 -> 0
C33: PRM Medicare ACO Analytics (CCLF Only) | D33: =SUM(Calcs!D32:H32) -> 0 | F33: =(1-G33)*F18/SUM(F18,H18) -> 0 | G33: =MIN(1,G18+$H$20) -> 1 | H33: =IF(H18=0, 0,(1-G33)*H18/SUM(F18,H18)) -> 0 | I33: =IF(I18=0, 0,(1-G33)*I18/SUM(F18,I18)) -> 0 | K33: =F33*$D33 -> 0 | L33: =G33*$D33 -> 0 | M33: =H33*$D33 -> 0 | N33: =I33*$D33 -> 0
B35: Annual Base Product Fees (Marginal over data fees)
C36: ACO Insight - Basic | D36: =SUM(Calcs!D73:H73) -> 0 | F36: 0.9 | G36: 0.1 | H36: =1-SUM(F36:G36) -> 0 | I36: 0 | K36: =F36*$D36 -> 0 | L36: =G36*$D36 -> 0 | M36: =H36*$D36 -> 0 | N36: =I36*$D36 -> 0
C37: ACO Insight - Enhanced | D37: =SUM(Calcs!D74:H74) -> 14000 | F37: 0.9 | G37: 0.1 | H37: =1-SUM(F37:G37) -> 0 | I37: 0 | K37: =F37*$D37 -> 12600 | L37: =G37*$D37 -> 1400 | M37: =H37*$D37 -> 0 | N37: =I37*$D37 -> 0
C38: PRM Care Coordinator Report | D38: =SUM(Calcs!D75:H75) -> 0 | F38: 0.1 | G38: 0.9 | H38: =1-SUM(F38:G38) -> 0 | I38: 0 | K38: =F38*$D38 -> 0 | L38: =G38*$D38 -> 0 | M38: =H38*$D38 -> 0 | N38: =I38*$D38 -> 0
C39: PRM Physician Risk and Credibility Adjusted Report | D39: =SUM(Calcs!D76:H76) -> 0 | F39: 0.1 | G39: 0.9 | H39: =1-SUM(F39:G39) -> 0 | I39: 0 | K39: =F39*$D39 -> 0 | L39: =G39*$D39 -> 0 | M39: =H39*$D39 -> 0 | N39: =I39*$D39 -> 0
B41: Annual PMPM Add-on Product Fees (Marginal over data fees)
C42: ACO Insight - Basic | D42: =SUM(Calcs!D79:H79) -> 0 | F42: =IFERROR((1-G42)*F36/SUM(F36,H36),0) -> 0.8 | G42: =MIN(1,G36+$H$20) -> 0.2 | H42: =IFERROR((1-G42)*H36/SUM(F36,H36),0) -> 0 | I42: 0 | K42: =F42*$D42 -> 0 | L42: =G42*$D42 -> 0 | M42: =H42*$D42 -> 0 | N42: =I42*$D42 -> 0
C43: ACO Insight - Enhanced | D43: =SUM(Calcs!D80:H80) -> 0 | F43: =IFERROR((1-G43)*F37/SUM(F37,H37),0) -> 0.8 | G43: =MIN(1,G37+$H$20) -> 0.2 | H43: =IFERROR((1-G43)*H37/SUM(F37,H37),0) -> 0 | I43: 0 | K43: =F43*$D43 -> 0 | L43: =G43*$D43 -> 0 | M43: =H43*$D43 -> 0 | N43: =I43*$D43 -> 0
C44: PRM Care Coordinator Report | D44: =SUM(Calcs!D81:H81) -> 0 | F44: =IFERROR((1-G44)*F38/SUM(F38,H38),0) -> 0 | G44: =MIN(1,G38+$H$20) -> 1 | H44: =IFERROR((1-G44)*H38/SUM(F38,H38),0) -> 0 | I44: 0 | K44: =F44*$D44 -> 0 | L44: =G44*$D44 -> 0 | M44: =H44*$D44 -> 0 | N44: =I44*$D44 -> 0
C45: PRM Physician Risk and Credibility Adjusted Report | D45: =SUM(Calcs!D82:H82) -> 0 | F45: =IFERROR((1-G45)*F39/SUM(F39,H39),0) -> 0 | G45: =MIN(1,G39+$H$20) -> 1 | H45: =IFERROR((1-G45)*H39/SUM(F39,H39),0) -> 0 | I45: 0 | K45: =F45*$D45 -> 0 | L45: =G45*$D45 -> 0 | M45: =H45*$D45 -> 0 | N45: =I45*$D45 -> 0
...

Sheet Outputs_Timeline
F1: =COUNTIF(F3:F94,">0") -> 18 | H1: Implementation Fee | M1: Monthly Fees | S1: Quarterly Invoices
B2: Month | D2: Price Inflation | E2: Price Freeze | F2: Price Multiplier | H2: Total | I2: NY | J2: PRM | K2: MI | M2: Total | N2: NY | O2: PRM | P2: MI Royalties | Q2: Other Royalties | S2: Total | T2: NY | U2: PRM | V2: MI Royalties | W2: Other Royalties
B3: 42917 | D3: =1 -> 1 | E3: =IF(B3=Inputs!$C$1,D3,1) -> 1 | F3: =IF(AND(B3>=Inputs!$C$1,B3<EDATE(Inputs!$C$1,Inputs!$C$2)),E3,0) -> 0 | H3: =IF($B3=Inputs!$C$1,SUM(Outputs_Internal!$D$4, Outputs_Internal!$D$5),0)*$D3 -> 0 | I3: =IF($B3=Inputs!$C$1,SUM(Outputs_Internal!K$4, Outputs_Internal!K$5),0)*$D3 -> 0 | J3: =IF($B3=Inputs!$C$1,SUM(Outputs_Internal!L$4, Outputs_Internal!L$5),0)*$D3 -> 0 | K3: =IF($B3=Inputs!$C$1,SUM(Outputs_Internal!M$4, Outputs_Internal!$M$5),0)*$D3 -> 0 | M3: =$F3*Outputs_Internal!$D$52/12 -> 0 | N3: =$F3*Outputs_Internal!K$52/12 -> 0 | O3: =$F3*Outputs_Internal!L$52/12 -> 0 | P3: =$F3*Outputs_Internal!M$52/12 -> 0 | Q3: =$F3*Outputs_Internal!N$52/12 -> 0
B4: =EDATE(B3,1) -> 42948 | D4: =D3*IF(AND(MONTH(B4)=1,YEAR(B4)>=YEAR(Prices!$I$15)),1+Prices!$I$14,1) -> 1 | E4: =IF(B4=Inputs!$C$1,D4,E3) -> 1 | F4: =IF(AND(B4>=Inputs!$C$1,B4<EDATE(Inputs!$C$1,Inputs!$C$2)),E4,0) -> 0 | H4: =IF($B4=Inputs!$C$1,SUM(Outputs_Internal!$D$4, Outputs_Internal!$D$5),0)*$D4 -> 0 | I4: =IF($B4=Inputs!$C$1,SUM(Outputs_Internal!K$4, Outputs_Internal!K$5),0)*$D4 -> 0 | J4: =IF($B4=Inputs!$C$1,SUM(Outputs_Internal!L$4, Outputs_Internal!L$5),0)*$D4 -> 0 | K4: =IF($B4=Inputs!$C$1,SUM(Outputs_Internal!M$4, Outputs_Internal!$M$5),0)*$D4 -> 0 | M4: =$F4*Outputs_Internal!$D$52/12 -> 0 | N4: =$F4*Outputs_Internal!K$52/12 -> 0 | O4: =$F4*Outputs_Internal!L$52/12 -> 0 | P4: =$F4*Outputs_Internal!M$52/12 -> 0 | Q4: =$F4*Outputs_Internal!N$52/12 -> 0
B5: =EDATE(B4,1) -> 42979 | D5: =D4*IF(AND(MONTH(B5)=1,YEAR(B5)>=YEAR(Prices!$I$15)),1+Prices!$I$14,1) -> 1 | E5: =IF(B5=Inputs!$C$1,D5,E4) -> 1 | F5: =IF(AND(B5>=Inputs!$C$1,B5<EDATE(Inputs!$C$1,Inputs!$C$2)),E5,0) -> 0 | H5: =IF($B5=Inputs!$C$1,SUM(Outputs_Internal!$D$4, Outputs_Internal!$D$5),0)*$D5 -> 0 | I5: =IF($B5=Inputs!$C$1,SUM(Outputs_Internal!K$4, Outputs_Internal!K$5),0)*$D5 -> 0 | J5: =IF($B5=Inputs!$C$1,SUM(Outputs_Internal!L$4, Outputs_Internal!L$5),0)*$D5 -> 0 | K5: =IF($B5=Inputs!$C$1,SUM(Outputs_Internal!M$4, Outputs_Internal!$M$5),0)*$D5 -> 0 | M5: =$F5*Outputs_Internal!$D$52/12 -> 0 | N5: =$F5*Outputs_Internal!K$52/12 -> 0 | O5: =$F5*Outputs_Internal!L$52/12 -> 0 | P5: =$F5*Outputs_Internal!M$52/12 -> 0 | Q5: =$F5*Outputs_Internal!N$52/12 -> 0 | S5: =IF(MOD(MONTH($B5),3)=0,SUM(H3:H5,M3:M5),0) -> 0 | T5: =IF(MOD(MONTH($B5),3)=0,SUM(I3:I5,N3:N5),0) -> 0 | U5: =IF(MOD(MONTH($B5),3)=0,SUM(J3:J5,O3:O5),0) -> 0 | V5: =IF(MOD(MONTH($B5),3)=0,SUM(K3:K5,P3:P5),0) -> 0 | W5: =IF(MOD(MONTH($B5),3)=0,SUM(L3:L5,Q3:Q5),0) -> 0
B6: =EDATE(B5,1) -> 43009 | D6: =D5*IF(AND(MONTH(B6)=1,YEAR(B6)>=YEAR(Prices!$I$15)),1+Prices!$I$14,1) -> 1 | E6: =IF(B6=Inputs!$C$1,D6,E5) -> 1 | F6: =IF(AND(B6>=Inputs!$C$1,B6<EDATE(Inputs!$C$1,Inputs!$C$2)),E6,0) -> 0 | H6: =IF($B6=Inputs!$C$1,SUM(Outputs_Internal!$D$4, Outputs_Internal!$D$5),0)*$D6 -> 0 | I6: =IF($B6=Inputs!$C$1,SUM(Outputs_Internal!K$4, Outputs_Internal!K$5),0)*$D6 -> 0 | J6: =IF($B6=Inputs!$C$1,SUM(Outputs_Internal!L$4, Outputs_Internal!L$5),0)*$D6 -> 0 | K6: =IF($B6=Inputs!$C$1,SUM(Outputs_Internal!M$4, Outputs_Internal!$M$5),0)*$D6 -> 0 | M6: =$F6*Outputs_Internal!$D$52/12 -> 0 | N6: =$F6*Outputs_Internal!K$52/12 -> 0 | O6: =$F6*Outputs_Internal!L$52/12 -> 0 | P6: =$F6*Outputs_Internal!M$52/12 -> 0 | Q6: =$F6*Outputs_Internal!N$52/12 -> 0 | S6: =IF(MOD(MONTH($B6),3)=0,SUM(H4:H6,M4:M6),0) -> 0 | T6: =IF(MOD(MONTH($B6),3)=0,SUM(I4:I6,N4:N6),0) -> 0 | U6: =IF(MOD(MONTH($B6),3)=0,SUM(J4:J6,O4:O6),0) -> 0 | V6: =IF(MOD(MONTH($B6),3)=0,SUM(K4:K6,P4:P6),0) -> 0 | W6: =IF(MOD(MONTH($B6),3)=0,SUM(L4:L6,Q4:Q6),0) -> 0
B7: =EDATE(B6,1) -> 43040 | D7: =D6*IF(AND(MONTH(B7)=1,YEAR(B7)>=YEAR(Prices!$I$15)),1+Prices!$I$14,1) -> 1 | E7: =IF(B7=Inputs!$C$1,D7,E6) -> 1 | F7: =IF(AND(B7>=Inputs!$C$1,B7<EDATE(Inputs!$C$1,Inputs!$C$2)),E7,0) -> 0 | H7: =IF($B7=Inputs!$C$1,SUM(Outputs_Internal!$D$4, Outputs_Internal!$D$5),0)*$D7 -> 0 | I7: =IF($B7=Inputs!$C$1,SUM(Outputs_Internal!K$4, Outputs_Internal!K$5),0)*$D7 -> 0 | J7: =IF($B7=Inputs!$C$1,SUM(Outputs_Internal!L$4, Outputs_Internal!L$5),0)*$D7 -> 0 | K7: =IF($B7=Inputs!$C$1,SUM(Outputs_Internal!M$4, Outputs_Internal!$M$5),0)*$D7 -> 0 | M7: =$F7*Outputs_Internal!$D$52/12 -> 0 | N7: =$F7*Outputs_Internal!K$52/12 -> 0 | O7: =$F7*Outputs_Internal!L$52/12 -> 0 | P7: =$F7*Outputs_Internal!M$52/12 -> 0 | Q7: =$F7*Outputs_Internal!N$52/12 -> 0 | S7: =IF(MOD(MONTH($B7),3)=0,SUM(H5:H7,M5:M7),0) -> 0 | T7: =IF(MOD(MONTH($B7),3)=0,SUM(I5:I7,N5:N7),0) -> 0 | U7: =IF(MOD(MONTH($B7),3)=0,SUM(J5:J7,O5:O7),0) -> 0 | V7: =IF(MOD(MONTH($B7),3)=0,SUM(K5:K7,P5:P7),0) -> 0 | W7: =IF(MOD(MONTH($B7),3)=0,SUM(L5:L7,Q5:Q7),0) -> 0
B8: =EDATE(B7,1) -> 43070 | D8: =D7*IF(AND(MONTH(B8)=1,YEAR(B8)>=YEAR(Prices!$I$15)),1+Prices!$I$14,1) -> 1 | E8: =IF(B8=Inputs!$C$1,D8,E7) -> 1 | F8: =IF(AND(B8>=Inputs!$C$1,B8<EDATE(Inputs!$C$1,Inputs!$C$2)),E8,0) -> 0 | H8: =IF($B8=Inputs!$C$1,SUM(Outputs_Internal!$D$4, Outputs_Internal!$D$5),0)*$D8 -> 0 | I8: =IF($B8=Inputs!$C$1,SUM(Outputs_Internal!K$4, Outputs_Internal!K$5),0)*$D8 -> 0 | J8: =IF($B8=Inputs!$C$1,SUM(Outputs_Internal!L$4, Outputs_Internal!L$5),0)*$D8 -> 0 | K8: =IF($B8=Inputs!$C$1,SUM(Outputs_Internal!M$4, Outputs_Internal!$M$5),0)*$D8 -> 0 | M8: =$F8*Outputs_Internal!$D$52/12 -> 0 | N8: =$F8*Outputs_Internal!K$52/12 -> 0 | O8: =$F8*Outputs_Internal!L$52/12 -> 0 | P8: =$F8*Outputs_Internal!M$52/12 -> 0 | Q8: =$F8*Outputs_Internal!N$52/12 -> 0 | S8: =IF(MOD(MONTH($B8),3)=0,SUM(H6:H8,M6:M8),0) -> 0 | T8: =IF(MOD(MONTH($B8),3)=0,SUM(I6:I8,N6:N8),0) -> 0 | U8: =IF(MOD(MONTH($B8),3)=0,SUM(J6:J8,O6:O8),0) -> 0 | V8: =IF(MOD(MONTH($B8),3)=0,SUM(K6:K8,P6:P8),0) -> 0 | W8: =IF(MOD(MONTH($B8),3)=0,SUM(L6:L8,Q6:Q8),0) -> 0
B9: =EDATE(B8,1) -> 43101 | D9: =D8*IF(AND(MONTH(B9)=1,YEAR(B9)>=YEAR(Prices!$I$15)),1+Prices!$I$14,1) -> 1 | E9: =IF(B9=Inputs!$C$1,D9,E8) -> 1 | F9: =IF(AND(B9>=Inputs!$C$1,B9<EDATE(Inputs!$C$1,Inputs!$C$2)),E9,0) -> 1 | H9: =IF($B9=Inputs!$C$1,SUM(Outputs_Internal!$D$4, Outputs_Internal!$D$5),0)*$D9 -> 0 | I9: =IF($B9=Inputs!$C$1,SUM(Outputs_Internal!K$4, Outputs_Internal!K$5),0)*$D9 -> 0 | J9: =IF($B9=Inputs!$C$1,SUM(Outputs_Internal!L$4, Outputs_Internal!L$5),0)*$D9 -> 0 | K9: =IF($B9=Inputs!$C$1,SUM(Outputs_Internal!M$4, Outputs_Internal!$M$5),0)*$D9 -> 0 | M9: =$F9*Outputs_Internal!$D$52/12 -> 4268.75 | N9: =$F9*Outputs_Internal!K$52/12 -> 2093.4418 | O9: =$F9*Outputs_Internal!L$52/12 -> 1769.8744 | P9: =$F9*Outputs_Internal!M$52/12 -> 374.24658 | Q9: =$F9*Outputs_Internal!N$52/12 -> 31.187215 | S9: =IF(MOD(MONTH($B9),3)=0,SUM(H7:H9,M7:M9),0) -> 0 | T9: =IF(MOD(MONTH($B9),3)=0,SUM(I7:I9,N7:N9),0) -> 0 | U9: =IF(MOD(MONTH($B9),3)=0,SUM(J7:J9,O7:O9),0) -> 0 | V9: =IF(MOD(MONTH($B9),3)=0,SUM(K7:K9,P7:P9),0) -> 0 | W9: =IF(MOD(MONTH($B9),3)=0,SUM(L7:L9,Q7:Q9),0) -> 0
B10: =EDATE(B9,1) -> 43132 | D10: =D9*IF(AND(MONTH(B10)=1,YEAR(B10)>=YEAR(Prices!$I$15)),1+Prices!$I$14,1) -> 1 | E10: =IF(B10=Inputs!$C$1,D10,E9) -> 1 | F10: =IF(AND(B10>=Inputs!$C$1,B10<EDATE(Inputs!$C$1,Inputs!$C$2)),E10,0) -> 1 | H10: =IF($B10=Inputs!$C$1,SUM(Outputs_Internal!$D$4, Outputs_Internal!$D$5),0)*$D10 -> 0 | I10: =IF($B10=Inputs!$C$1,SUM(Outputs_Internal!K$4, Outputs_Internal!K$5),0)*$D10 -> 0 | J10: =IF($B10=Inputs!$C$1,SUM(Outputs_Internal!L$4, Outputs_Internal!L$5),0)*$D10 -> 0 | K10: =IF($B10=Inputs!$C$1,SUM(Outputs_Internal!M$4, Outputs_Internal!$M$5),0)*$D10 -> 0 | M10: =$F10*Outputs_Internal!$D$52/12 -> 4268.75 | N10: =$F10*Outputs_Internal!K$52/12 -> 2093.4418 | O10: =$F10*Outputs_Internal!L$52/12 -> 1769.8744 | P10: =$F10*Outputs_Internal!M$52/12 -> 374.24658 | Q10: =$F10*Outputs_Internal!N$52/12 -> 31.187215 | S10: =IF(MOD(MONTH($B10),3)=0,SUM(H8:H10,M8:M10),0) -> 0 | T10: =IF(MOD(MONTH($B10),3)=0,SUM(I8:I10,N8:N10),0) -> 0 | U10: =IF(MOD(MONTH($B10),3)=0,SUM(J8:J10,O8:O10),0) -> 0 | V10: =IF(MOD(MONTH($B10),3)=0,SUM(K8:K10,P8:P10),0) -> 0 | W10: =IF(MOD(MONTH($B10),3)=0,SUM(L8:L10,Q8:Q10),0) -> 0
B11: =EDATE(B10,1) -> 43160 | D11: =D10*IF(AND(MONTH(B11)=1,YEAR(B11)>=YEAR(Prices!$I$15)),1+Prices!$I$14,1) -> 1 | E11: =IF(B11=Inputs!$C$1,D11,E10) -> 1 | F11: =IF(AND(B11>=Inputs!$C$1,B11<EDATE(Inputs!$C$1,Inputs!$C$2)),E11,0) -> 1 | H11: =IF($B11=Inputs!$C$1,SUM(Outputs_Internal!$D$4, Outputs_Internal!$D$5),0)*$D11 -> 0 | I11: =IF($B11=Inputs!$C$1,SUM(Outputs_Internal!K$4, Outputs_Internal!K$5),0)*$D11 -> 0 | J11: =IF($B11=Inputs!$C$1,SUM(Outputs_Internal!L$4, Outputs_Internal!L$5),0)*$D11 -> 0 | K11: =IF($B11=Inputs!$C$1,SUM(Outputs_Internal!M$4, Outputs_Internal!$M$5),0)*$D11 -> 0 | M11: =$F11*Outputs_Internal!$D$52/12 -> 4268.75 | N11: =$F11*Outputs_Internal!K$52/12 -> 2093.4418 | O11: =$F11*Outputs_Internal!L$52/12 -> 1769.8744 | P11: =$F11*Outputs_Internal!M$52/12 -> 374.24658 | Q11: =$F11*Outputs_Internal!N$52/12 -> 31.187215 | S11: =IF(MOD(MONTH($B11),3)=0,SUM(H9:H11,M9:M11),0) -> 12806.25 | T11: =IF(MOD(MONTH($B11),3)=0,SUM(I9:I11,N9:N11),0) -> 6280.3253 | U11: =IF(MOD(MONTH($B11),3)=0,SUM(J9:J11,O9:O11),0) -> 5309.6233 | V11: =IF(MOD(MONTH($B11),3)=0,SUM(K9:K11,P9:P11),0) -> 1122.7397 | W11: =IF(MOD(MONTH($B11),3)=0,SUM(L9:L11,Q9:Q11),0) -> 93.561644
B12: =EDATE(B11,1) -> 43191 | D12: =D11*IF(AND(MONTH(B12)=1,YEAR(B12)>=YEAR(Prices!$I$15)),1+Prices!$I$14,1) -> 1 | E12: =IF(B12=Inputs!$C$1,D12,E11) -> 1 | F12: =IF(AND(B12>=Inputs!$C$1,B12<EDATE(Inputs!$C$1,Inputs!$C$2)),E12,0) -> 1 | H12: =IF($B12=Inputs!$C$1,SUM(Outputs_Internal!$D$4, Outputs_Internal!$D$5),0)*$D12 -> 0 | I12: =IF($B12=Inputs!$C$1,SUM(Outputs_Internal!K$4, Outputs_Internal!K$5),0)*$D12 -> 0 | J12: =IF($B12=Inputs!$C$1,SUM(Outputs_Internal!L$4, Outputs_Internal!L$5),0)*$D12 -> 0 | K12: =IF($B12=Inputs!$C$1,SUM(Outputs_Internal!M$4, Outputs_Internal!$M$5),0)*$D12 -> 0 | M12: =$F12*Outputs_Internal!$D$52/12 -> 4268.75 | N12: =$F12*Outputs_Internal!K$52/12 -> 2093.4418 | O12: =$F12*Outputs_Internal!L$52/12 -> 1769.8744 | P12: =$F12*Outputs_Internal!M$52/12 -> 374.24658 | Q12: =$F12*Outputs_Internal!N$52/12 -> 31.187215 | S12: =IF(MOD(MONTH($B12),3)=0,SUM(H10:H12,M10:M12),0) -> 0 | T12: =IF(MOD(MONTH($B12),3)=0,SUM(I10:I12,N10:N12),0) -> 0 | U12: =IF(MOD(MONTH($B12),3)=0,SUM(J10:J12,O10:O12),0) -> 0 | V12: =IF(MOD(MONTH($B12),3)=0,SUM(K10:K12,P10:P12),0) -> 0 | W12: =IF(MOD(MONTH($B12),3)=0,SUM(L10:L12,Q10:Q12),0) -> 0
B13: =EDATE(B12,1) -> 43221 | D13: =D12*IF(AND(MONTH(B13)=1,YEAR(B13)>=YEAR(Prices!$I$15)),1+Prices!$I$14,1) -> 1 | E13: =IF(B13=Inputs!$C$1,D13,E12) -> 1 | F13: =IF(AND(B13>=Inputs!$C$1,B13<EDATE(Inputs!$C$1,Inputs!$C$2)),E13,0) -> 1 | H13: =IF($B13=Inputs!$C$1,SUM(Outputs_Internal!$D$4, Outputs_Internal!$D$5),0)*$D13 -> 0 | I13: =IF($B13=Inputs!$C$1,SUM(Outputs_Internal!K$4, Outputs_Internal!K$5),0)*$D13 -> 0 | J13: =IF($B13=Inputs!$C$1,SUM(Outputs_Internal!L$4, Outputs_Internal!L$5),0)*$D13 -> 0 | K13: =IF($B13=Inputs!$C$1,SUM(Outputs_Internal!M$4, Outputs_Internal!$M$5),0)*$D13 -> 0 | M13: =$F13*Outputs_Internal!$D$52/12 -> 4268.75 | N13: =$F13*Outputs_Internal!K$52/12 -> 2093.4418 | O13: =$F13*Outputs_Internal!L$52/12 -> 1769.8744 | P13: =$F13*Outputs_Internal!M$52/12 -> 374.24658 | Q13: =$F13*Outputs_Internal!N$52/12 -> 31.187215 | S13: =IF(MOD(MONTH($B13),3)=0,SUM(H11:H13,M11:M13),0) -> 0 | T13: =IF(MOD(MONTH($B13),3)=0,SUM(I11:I13,N11:N13),0) -> 0 | U13: =IF(MOD(MONTH($B13),3)=0,SUM(J11:J13,O11:O13),0) -> 0 | V13: =IF(MOD(MONTH($B13),3)=0,SUM(K11:K13,P11:P13),0) -> 0 | W13: =IF(MOD(MONTH($B13),3)=0,SUM(L11:L13,Q11:Q13),0) -> 0
B14: =EDATE(B13,1) -> 43252 | D14: =D13*IF(AND(MONTH(B14)=1,YEAR(B14)>=YEAR(Prices!$I$15)),1+Prices!$I$14,1) -> 1 | E14: =IF(B14=Inputs!$C$1,D14,E13) -> 1 | F14: =IF(AND(B14>=Inputs!$C$1,B14<EDATE(Inputs!$C$1,Inputs!$C$2)),E14,0) -> 1 | H14: =IF($B14=Inputs!$C$1,SUM(Outputs_Internal!$D$4, Outputs_Internal!$D$5),0)*$D14 -> 0 | I14: =IF($B14=Inputs!$C$1,SUM(Outputs_Internal!K$4, Outputs_Internal!K$5),0)*$D14 -> 0 | J14: =IF($B14=Inputs!$C$1,SUM(Outputs_Internal!L$4, Outputs_Internal!L$5),0)*$D14 -> 0 | K14: =IF($B14=Inputs!$C$1,SUM(Outputs_Internal!M$4, Outputs_Internal!$M$5),0)*$D14 -> 0 | M14: =$F14*Outputs_Internal!$D$52/12 -> 4268.75 | N14: =$F14*Outputs_Internal!K$52/12 -> 2093.4418 | O14: =$F14*Outputs_Internal!L$52/12 -> 1769.8744 | P14: =$F14*Outputs_Internal!M$52/12 -> 374.24658 | Q14: =$F14*Outputs_Internal!N$52/12 -> 31.187215 | S14: =IF(MOD(MONTH($B14),3)=0,SUM(H12:H14,M12:M14),0) -> 12806.25 | T14: =IF(MOD(MONTH($B14),3)=0,SUM(I12:I14,N12:N14),0) -> 6280.3253 | U14: =IF(MOD(MONTH($B14),3)=0,SUM(J12:J14,O12:O14),0) -> 5309.6233 | V14: =IF(MOD(MONTH($B14),3)=0,SUM(K12:K14,P12:P14),0) -> 1122.7397 | W14: =IF(MOD(MONTH($B14),3)=0,SUM(L12:L14,Q12:Q14),0) -> 93.561644
B15: =EDATE(B14,1) -> 43282 | D15: =D14*IF(AND(MONTH(B15)=1,YEAR(B15)>=YEAR(Prices!$I$15)),1+Prices!$I$14,1) -> 1 | E15: =IF(B15=Inputs!$C$1,D15,E14) -> 1 | F15: =IF(AND(B15>=Inputs!$C$1,B15<EDATE(Inputs!$C$1,Inputs!$C$2)),E15,0) -> 1 | H15: =IF($B15=Inputs!$C$1,SUM(Outputs_Internal!$D$4, Outputs_Internal!$D$5),0)*$D15 -> 0 | I15: =IF($B15=Inputs!$C$1,SUM(Outputs_Internal!K$4, Outputs_Internal!K$5),0)*$D15 -> 0 | J15: =IF($B15=Inputs!$C$1,SUM(Outputs_Internal!L$4, Outputs_Internal!L$5),0)*$D15 -> 0 | K15: =IF($B15=Inputs!$C$1,SUM(Outputs_Internal!M$4, Outputs_Internal!$M$5),0)*$D15 -> 0 | M15: =$F15*Outputs_Internal!$D$52/12 -> 4268.75 | N15: =$F15*Outputs_Internal!K$52/12 -> 2093.4418 | O15: =$F15*Outputs_Internal!L$52/12 -> 1769.8744 | P15: =$F15*Outputs_Internal!M$52/12 -> 374.24658 | Q15: =$F15*Outputs_Internal!N$52/12 -> 31.187215 | S15: =IF(MOD(MONTH($B15),3)=0,SUM(H13:H15,M13:M15),0) -> 0 | T15: =IF(MOD(MONTH($B15),3)=0,SUM(I13:I15,N13:N15),0) -> 0 | U15: =IF(MOD(MONTH($B15),3)=0,SUM(J13:J15,O13:O15),0) -> 0 | V15: =IF(MOD(MONTH($B15),3)=0,SUM(K13:K15,P13:P15),0) -> 0 | W15: =IF(MOD(MONTH($B15),3)=0,SUM(L13:L15,Q13:Q15),0) -> 0
B16: =EDATE(B15,1) -> 43313 | D16: =D15*IF(AND(MONTH(B16)=1,YEAR(B16)>=YEAR(Prices!$I$15)),1+Prices!$I$14,1) -> 1 | E16: =IF(B16=Inputs!$C$1,D16,E15) -> 1 | F16: =IF(AND(B16>=Inputs!$C$1,B16<EDATE(Inputs!$C$1,Inputs!$C$2)),E16,0) -> 1 | H16: =IF($B16=Inputs!$C$1,SUM(Outputs_Internal!$D$4, Outputs_Internal!$D$5),0)*$D16 -> 0 | I16: =IF($B16=Inputs!$C$1,SUM(Outputs_Internal!K$4, Outputs_Internal!K$5),0)*$D16 -> 0 | J16: =IF($B16=Inputs!$C$1,SUM(Outputs_Internal!L$4, Outputs_Internal!L$5),0)*$D16 -> 0 | K16: =IF($B16=Inputs!$C$1,SUM(Outputs_Internal!M$4, Outputs_Internal!$M$5),0)*$D16 -> 0 | M16: =$F16*Outputs_Internal!$D$52/12 -> 4268.75 | N16: =$F16*Outputs_Internal!K$52/12 -> 2093.4418 | O16: =$F16*Outputs_Internal!L$52/12 -> 1769.8744 | P16: =$F16*Outputs_Internal!M$52/12 -> 374.24658 | Q16: =$F16*Outputs_Internal!N$52/12 -> 31.187215 | S16: =IF(MOD(MONTH($B16),3)=0,SUM(H14:H16,M14:M16),0) -> 0 | T16: =IF(MOD(MONTH($B16),3)=0,SUM(I14:I16,N14:N16),0) -> 0 | U16: =IF(MOD(MONTH($B16),3)=0,SUM(J14:J16,O14:O16),0) -> 0 | V16: =IF(MOD(MONTH($B16),3)=0,SUM(K14:K16,P14:P16),0) -> 0 | W16: =IF(MOD(MONTH($B16),3)=0,SUM(L14:L16,Q14:Q16),0) -> 0
... B94: =EDATE(B93,1) -> 45689 | D94: =D93*IF(AND(MONTH(B94)=1,YEAR(B94)>=YEAR(Prices!$I$15)),1+Prices!$I$14,1) -> 1.0908505 | E94: =IF(B94=Inputs!$C$1,D94,E93) -> 1 | F94: =IF(AND(B94>=Inputs!$C$1,B94<EDATE(Inputs!$C$1,Inputs!$C$2)),E94,0) -> 0 | H94: =IF($B94=Inputs!$C$1,SUM(Outputs_Internal!$D$4, Outputs_Internal!$D$5),0)*$D94 -> 0 | I94: =IF($B94=Inputs!$C$1,SUM(Outputs_Internal!K$4, Outputs_Internal!K$5),0)*$D94 -> 0 | J94: =IF($B94=Inputs!$C$1,SUM(Outputs_Internal!L$4, Outputs_Internal!L$5),0)*$D94 -> 0 | K94: =IF($B94=Inputs!$C$1,SUM(Outputs_Internal!M$4, Outputs_Internal!$M$5),0)*$D94 -> 0 | M94: =$F94*Outputs_Internal!$D$52/12 -> 0 | N94: =$F94*Outputs_Internal!K$52/12 -> 0 | O94: =$F94*Outputs_Internal!L$52/12 -> 0 | P94: =$F94*Outputs_Internal!M$52/12 -> 0 | Q94: =$F94*Outputs_Internal!N$52/12 -> 0 | S94: =IF(MOD(MONTH($B94),3)=0,SUM(H92:H94,M92:M94),0) -> 0 | T94: =IF(MOD(MONTH($B94),3)=0,SUM(I92:I94,N92:N94),0) -> 0 | U94: =IF(MOD(MONTH($B94),3)=0,SUM(J92:J94,O92:O94),0) -> 0 | V94: =IF(MOD(MONTH($B94),3)=0,SUM(K92:K94,P92:P94),0) -> 0 | W94: =IF(MOD(MONTH($B94),3)=0,SUM(L92:L94,Q92:Q94),0) -> 0

Sheet Calcs
D2: Data Feed #1 | E2: Data Feed #2 | F2: Data Feed #3 | G2: Data Feed #4 | H2: Data Feed #5 | K2: Product Ranking #1 | L2: Product Ranking #2 | M2: Product Ranking #3 | N2: Product Ranking #4 | O2: Product Ranking #5
B3: One-Time Fees:
C4: Implementation | D4: =IF(AND(Inputs!D5="Y",Inputs!D4="Y"), 0, IF(Inputs!D4="Y", SUM(Prices!$C$3, IF(Inputs!D$6 ="Y", Prices!$C$4, 0)), IF(Inputs!D4="N", Prices!$D$3, 0))) -> 0 | E4: =IF(AND(Inputs!E5="Y",Inputs!E4="Y"), 0, IF(Inputs!E4="Y", SUM(Prices!$C$3, IF(Inputs!E$6 ="Y", Prices!$C$4, 0)), IF(Inputs!E4="N", Prices!$D$3, 0))) -> 0 | F4: =IF(AND(Inputs!F5="Y",Inputs!F4="Y"), 0, IF(Inputs!F4="Y", SUM(Prices!$C$3, IF(Inputs!F$6 ="Y", Prices!$C$4, 0)), IF(Inputs!F4="N", Prices!$D$3, 0))) -> 0 | G4: =IF(AND(Inputs!G5="Y",Inputs!G4="Y"), 0, IF(Inputs!G4="Y", SUM(Prices!$C$3, IF(Inputs!G$6 ="Y", Prices!$C$4, 0)), IF(Inputs!G4="N", Prices!$D$3, 0))) -> 0 | H4: =IF(AND(Inputs!H5="Y",Inputs!H4="Y"), 0, IF(Inputs!H4="Y", SUM(Prices!$C$3, IF(Inputs!H$6 ="Y", Prices!$C$4, 0)), IF(Inputs!H4="N", Prices!$D$3, 0))) -> 0
B6: Patients Above 25,000 (Non-CCLF Only) | D6: =IF(Inputs!D4="N",MAX(Inputs!D7-25000,0),0) -> 0 | E6: =IF(Inputs!E4="N",MAX(Inputs!E7-25000,0),) -> 0 | F6: =IF(Inputs!F4="N",MAX(Inputs!F7-25000,0),) -> 0 | G6: =IF(Inputs!G4="N",MAX(Inputs!G7-25000,0),) -> 0 | H6: =IF(Inputs!H4="N",MAX(Inputs!H7-25000,0),) -> 0
B8: Annual Base Data Fees (With Implicit forces):
C9: Base Processing Fee | D9: =IF(Inputs!D4="Y", Prices!$C$6, IF(Inputs!D4="N", Prices!$D$6, 0)) -> 15000 | E9: =IF(Inputs!E4="Y", Prices!$C$6, IF(Inputs!E4="N", Prices!$D$6, 0)) -> 0 | F9: =IF(Inputs!F4="Y", Prices!$C$6, IF(Inputs!F4="N", Prices!$D$6, 0)) -> 0 | G9: =IF(Inputs!G4="Y", Prices!$C$6, IF(Inputs!G4="N", Prices!$D$6, 0)) -> 0 | H9: =IF(Inputs!H4="Y", Prices!$C$6, IF(Inputs!H4="N", Prices!$D$6, 0)) -> 0
C10: Datamart Fee | D10: =IF(Inputs!D8="Y", Prices!$C$7, 0) -> 6750 | E10: =IF(Inputs!E8="Y", Prices!$C$7, 0) -> 0 | F10: =IF(Inputs!F8="Y", Prices!$C$7, 0) -> 0 | G10: =IF(Inputs!G8="Y", Prices!$C$7, 0) -> 0 | H10: =IF(Inputs!H8="Y", Prices!$C$7, 0) -> 0
C11: HCC Risk Scores | D11: =IF(OR(Inputs!D9="Y",Inputs!D$19="Y"), Prices!$C10, 0) -> 1000 | E11: =IF(OR(Inputs!E9="Y",Inputs!E$19="Y"), Prices!$C10, 0) -> 0 | F11: =IF(OR(Inputs!F9="Y",Inputs!F$19="Y"), Prices!$C10, 0) -> 0 | G11: =IF(OR(Inputs!G9="Y",Inputs!G$19="Y"), Prices!$C10, 0) -> 0 | H11: =IF(OR(Inputs!H9="Y",Inputs!H$19="Y"), Prices!$C10, 0) -> 0
C12: HCG Benchmarks | D12: =IF(OR(Inputs!D10="Y",Inputs!D$19="Y"), Prices!$C11, 0) -> 4000 | E12: =IF(OR(Inputs!E10="Y",Inputs!E$19="Y"), Prices!$C11, 0) -> 0 | F12: =IF(OR(Inputs!F10="Y",Inputs!F$19="Y"), Prices!$C11, 0) -> 0 | G12: =IF(OR(Inputs!G10="Y",Inputs!G$19="Y"), Prices!$C11, 0) -> 0 | H12: =IF(OR(Inputs!H10="Y",Inputs!H$19="Y"), Prices!$C11, 0) -> 0
C13: PAC/Grouping/Benchmarks | D13: =IF(OR(Inputs!D11="Y",Inputs!D$19="Y"), Prices!$C12, 0) -> 2000 | E13: =IF(OR(Inputs!E11="Y",Inputs!E$19="Y"), Prices!$C12, 0) -> 0 | F13: =IF(OR(Inputs!F11="Y",Inputs!F$19="Y"), Prices!$C12, 0) -> 0 | G13: =IF(OR(Inputs!G11="Y",Inputs!G$19="Y"), Prices!$C12, 0) -> 0 | H13: =IF(OR(Inputs!H11="Y",Inputs!H$19="Y"), Prices!$C12, 0) -> 0
C14: Key Claims Metrics | D14: =IF(OR(Inputs!D12="Y",Inputs!D$19="Y"), Prices!$C13, 0) -> 2000 | E14: =IF(OR(Inputs!E12="Y",Inputs!E$19="Y"), Prices!$C13, 0) -> 0 | F14: =IF(OR(Inputs!F12="Y",Inputs!F$19="Y"), Prices!$C13, 0) -> 0 | G14: =IF(OR(Inputs!G12="Y",Inputs!G$19="Y"), Prices!$C13, 0) -> 0 | H14: =IF(OR(Inputs!H12="Y",Inputs!H$19="Y"), Prices!$C13, 0) -> 0
C15: Waste Calculator | D15: =IF(OR(Inputs!D13="Y",Inputs!D$19="Y"), Prices!$C14, 0) -> 6000 | E15: =IF(OR(Inputs!E13="Y",Inputs!E$19="Y"), Prices!$C14, 0) -> 0 | F15: =IF(OR(Inputs!F13="Y",Inputs!F$19="Y"), Prices!$C14, 0) -> 0 | G15: =IF(OR(Inputs!G13="Y",Inputs!G$19="Y"), Prices!$C14, 0) -> 0 | H15: =IF(OR(Inputs!H13="Y",Inputs!H$19="Y"), Prices!$C14, 0) -> 0
C16: Medical Conditions | D16: =IF(OR(Inputs!D14="Y",Inputs!D$19="Y"), Prices!$C15, 0) -> 4000 | E16: =IF(OR(Inputs!E14="Y",Inputs!E$19="Y"), Prices!$C15, 0) -> 0 | F16: =IF(OR(Inputs!F14="Y",Inputs!F$19="Y"), Prices!$C15, 0) -> 0 | G16: =IF(OR(Inputs!G14="Y",Inputs!G$19="Y"), Prices!$C15, 0) -> 0 | H16: =IF(OR(Inputs!H14="Y",Inputs!H$19="Y"), Prices!$C15, 0) -> 0
C17: PRM Oppourtunity Prospective Scores | D17: =IF(OR(Inputs!D15="Y",Inputs!D$20="Y"), Prices!$C16, 0) -> 0 | E17: =IF(OR(Inputs!E15="Y",Inputs!E$20="Y"), Prices!$C16, 0) -> 0 | F17: =IF(OR(Inputs!F15="Y",Inputs!F$20="Y"), Prices!$C16, 0) -> 0 | G17: =IF(OR(Inputs!G15="Y",Inputs!G$20="Y"), Prices!$C16, 0) -> 0 | H17: =IF(OR(Inputs!H15="Y",Inputs!H$20="Y"), Prices!$C16, 0) -> 0
C18: PRM Conditions to Consider | D18: =IF(OR(Inputs!D16="Y",Inputs!D$20="Y"), Prices!$C17, 0) -> 0 | E18: =IF(OR(Inputs!E16="Y",Inputs!E$20="Y"), Prices!$C17, 0) -> 0 | F18: =IF(OR(Inputs!F16="Y",Inputs!F$20="Y"), Prices!$C17, 0) -> 0 | G18: =IF(OR(Inputs!G16="Y",Inputs!G$20="Y"), Prices!$C17, 0) -> 0 | H18: =IF(OR(Inputs!H16="Y",Inputs!H$20="Y"), Prices!$C17, 0) -> 0
C19: PRM Medicare ACO Analytics (CCLF Only) | D19: =IF(OR(Inputs!D17="Y",Inputs!D$20="Y"), Prices!$C18, 0) -> 0 | E19: =IF(OR(Inputs!E17="Y",Inputs!E$20="Y"), Prices!$C18, 0) -> 0 | F19: =IF(OR(Inputs!F17="Y",Inputs!F$20="Y"), Prices!$C18, 0) -> 0 | G19: =IF(OR(Inputs!G17="Y",Inputs!G$20="Y"), Prices!$C18, 0) -> 0 | H19: =IF(OR(Inputs!H17="Y",Inputs!H$20="Y"), Prices!$C18, 0) -> 0
B21: Annual PMPM Add-On Data Fees (With implicit forces):
C22: Base Processing Fee | D22: =IF(Inputs!D$4="Y", 0, IF(D$6 = "", "", PRODUCT(D$6, Prices!$E$6))) -> 0 | E22: =IF(Inputs!E$4="Y", 0, IF(E$6 = "", "", PRODUCT(E$6, Prices!$E$6))) -> 0 | F22: =IF(Inputs!F$4="Y", 0, IF(F$6 = "", "", PRODUCT(F$6, Prices!$E$6))) -> 0 | G22: =IF(Inputs!G$4="Y", 0, IF(G$6 = "", "", PRODUCT(G$6, Prices!$E$6))) -> 0 | H22: =IF(Inputs!H$4="Y", 0, IF(H$6 = "", "", PRODUCT(H$6, Prices!$E$6))) -> 0
C23: Datamart Fee | D23: 0 | E23: 0 | F23: 0 | G23: 0 | H23: 0
C24: HCC Risk Scores | D24: =IF(OR(Inputs!D$4="Y", D$6 = 0), 0, IF(OR(Inputs!D9="Y",Inputs!D$19="Y"),PRODUCT(D$6, Prices!$D10),0)) -> 0 | E24: =IF(OR(Inputs!E$4="Y", E$6 = 0), 0, IF(OR(Inputs!E9="Y",Inputs!E$19="Y"),PRODUCT(E$6, Prices!$D10),0)) -> 0 | F24: =IF(OR(Inputs!F$4="Y", F$6 = 0), 0, IF(OR(Inputs!F9="Y",Inputs!F$19="Y"),PRODUCT(F$6, Prices!$D10),0)) -> 0 | G24: =IF(OR(Inputs!G$4="Y", G$6 = 0), 0, IF(OR(Inputs!G9="Y",Inputs!G$19="Y"),PRODUCT(G$6, Prices!$D10),0)) -> 0 | H24: =IF(OR(Inputs!H$4="Y", H$6 = 0), 0, IF(OR(Inputs!H9="Y",Inputs!H$19="Y"),PRODUCT(H$6, Prices!$D10),0)) -> 0
C25: HCG Benchmarks | D25: =IF(OR(Inputs!D$4="Y", D$6 = 0), 0, IF(OR(Inputs!D10="Y",Inputs!D$19="Y"),PRODUCT(D$6, Prices!$D11),0)) -> 0 | E25: =IF(OR(Inputs!E$4="Y", E$6 = 0), 0, IF(OR(Inputs!E10="Y",Inputs!E$19="Y"),PRODUCT(E$6, Prices!$D11),0)) -> 0 | F25: =IF(OR(Inputs!F$4="Y", F$6 = 0), 0, IF(OR(Inputs!F10="Y",Inputs!F$19="Y"),PRODUCT(F$6, Prices!$D11),0)) -> 0 | G25: =IF(OR(Inputs!G$4="Y", G$6 = 0), 0, IF(OR(Inputs!G10="Y",Inputs!G$19="Y"),PRODUCT(G$6, Prices!$D11),0)) -> 0 | H25: =IF(OR(Inputs!H$4="Y", H$6 = 0), 0, IF(OR(Inputs!H10="Y",Inputs!H$19="Y"),PRODUCT(H$6, Prices!$D11),0)) -> 0
C26: PAC/Grouping/Benchmarks | D26: =IF(OR(Inputs!D$4="Y", D$6 = 0), 0, IF(OR(Inputs!D11="Y",Inputs!D$19="Y"),PRODUCT(D$6, Prices!$D12),0)) -> 0 | E26: =IF(OR(Inputs!E$4="Y", E$6 = 0), 0, IF(OR(Inputs!E11="Y",Inputs!E$19="Y"),PRODUCT(E$6, Prices!$D12),0)) -> 0 | F26: =IF(OR(Inputs!F$4="Y", F$6 = 0), 0, IF(OR(Inputs!F11="Y",Inputs!F$19="Y"),PRODUCT(F$6, Prices!$D12),0)) -> 0 | G26: =IF(OR(Inputs!G$4="Y", G$6 = 0), 0, IF(OR(Inputs!G11="Y",Inputs!G$19="Y"),PRODUCT(G$6, Prices!$D12),0)) -> 0 | H26: =IF(OR(Inputs!H$4="Y", H$6 = 0), 0, IF(OR(Inputs!H11="Y",Inputs!H$19="Y"),PRODUCT(H$6, Prices!$D12),0)) -> 0
C27: Key Claims Metrics | D27: =IF(OR(Inputs!D$4="Y", D$6 = 0), 0, IF(OR(Inputs!D12="Y",Inputs!D$19="Y"),PRODUCT(D$6, Prices!$D13),0)) -> 0 | E27: =IF(OR(Inputs!E$4="Y", E$6 = 0), 0, IF(OR(Inputs!E12="Y",Inputs!E$19="Y"),PRODUCT(E$6, Prices!$D13),0)) -> 0 | F27: =IF(OR(Inputs!F$4="Y", F$6 = 0), 0, IF(OR(Inputs!F12="Y",Inputs!F$19="Y"),PRODUCT(F$6, Prices!$D13),0)) -> 0 | G27: =IF(OR(Inputs!G$4="Y", G$6 = 0), 0, IF(OR(Inputs!G12="Y",Inputs!G$19="Y"),PRODUCT(G$6, Prices!$D13),0)) -> 0 | H27: =IF(OR(Inputs!H$4="Y", H$6 = 0), 0, IF(OR(Inputs!H12="Y",Inputs!H$19="Y"),PRODUCT(H$6, Prices!$D13),0)) -> 0
C28: Waste Calculator | D28: =IF(OR(Inputs!D$4="Y", D$6 = 0), 0, IF(OR(Inputs!D13="Y",Inputs!D$19="Y"),PRODUCT(D$6, Prices!$D14),0)) -> 0 | E28: =IF(OR(Inputs!E$4="Y", E$6 = 0), 0, IF(OR(Inputs!E13="Y",Inputs!E$19="Y"),PRODUCT(E$6, Prices!$D14),0)) -> 0 | F28: =IF(OR(Inputs!F$4="Y", F$6 = 0), 0, IF(OR(Inputs!F13="Y",Inputs!F$19="Y"),PRODUCT(F$6, Prices!$D14),0)) -> 0 | G28: =IF(OR(Inputs!G$4="Y", G$6 = 0), 0, IF(OR(Inputs!G13="Y",Inputs!G$19="Y"),PRODUCT(G$6, Prices!$D14),0)) -> 0 | H28: =IF(OR(Inputs!H$4="Y", H$6 = 0), 0, IF(OR(Inputs!H13="Y",Inputs!H$19="Y"),PRODUCT(H$6, Prices!$D14),0)) -> 0
C29: Medical Conditions | D29: =IF(OR(Inputs!D$4="Y", D$6 = 0), 0, IF(OR(Inputs!D14="Y",Inputs!D$19="Y"),PRODUCT(D$6, Prices!$D15),0)) -> 0 | E29: =IF(OR(Inputs!E$4="Y", E$6 = 0), 0, IF(OR(Inputs!E14="Y",Inputs!E$19="Y"),PRODUCT(E$6, Prices!$D15),0)) -> 0 | F29: =IF(OR(Inputs!F$4="Y", F$6 = 0), 0, IF(OR(Inputs!F14="Y",Inputs!F$19="Y"),PRODUCT(F$6, Prices!$D15),0)) -> 0 | G29: =IF(OR(Inputs!G$4="Y", G$6 = 0), 0, IF(OR(Inputs!G14="Y",Inputs!G$19="Y"),PRODUCT(G$6, Prices!$D15),0)) -> 0 | H29: =IF(OR(Inputs!H$4="Y", H$6 = 0), 0, IF(OR(Inputs!H14="Y",Inputs!H$19="Y"),PRODUCT(H$6, Prices!$D15),0)) -> 0
C30: PRM Oppourtunity Prospective Scores | D30: =IF(OR(Inputs!D$4="Y", D$6 = 0), 0, IF(OR(Inputs!D15="Y",Inputs!D$20="Y"),PRODUCT(D$6, Prices!$D16),0)) -> 0 | E30: =IF(OR(Inputs!E$4="Y", E$6 = 0), 0, IF(OR(Inputs!E15="Y",Inputs!E$20="Y"),PRODUCT(E$6, Prices!$D16),0)) -> 0 | F30: =IF(OR(Inputs!F$4="Y", F$6 = 0), 0, IF(OR(Inputs!F15="Y",Inputs!F$20="Y"),PRODUCT(F$6, Prices!$D16),0)) -> 0 | G30: =IF(OR(Inputs!G$4="Y", G$6 = 0), 0, IF(OR(Inputs!G15="Y",Inputs!G$20="Y"),PRODUCT(G$6, Prices!$D16),0)) -> 0 | H30: =IF(OR(Inputs!H$4="Y", H$6 = 0), 0, IF(OR(Inputs!H15="Y",Inputs!H$20="Y"),PRODUCT(H$6, Prices!$D16),0)) -> 0
C31: PRM Conditions to Consider | D31: =IF(OR(Inputs!D$4="Y", D$6 = 0), 0, IF(OR(Inputs!D16="Y",Inputs!D$20="Y"),PRODUCT(D$6, Prices!$D17),0)) -> 0 | E31: =IF(OR(Inputs!E$4="Y", E$6 = 0), 0, IF(OR(Inputs!E16="Y",Inputs!E$20="Y"),PRODUCT(E$6, Prices!$D17),0)) -> 0 | F31: =IF(OR(Inputs!F$4="Y", F$6 = 0), 0, IF(OR(Inputs!F16="Y",Inputs!F$20="Y"),PRODUCT(F$6, Prices!$D17),0)) -> 0 | G31: =IF(OR(Inputs!G$4="Y", G$6 = 0), 0, IF(OR(Inputs!G16="Y",Inputs!G$20="Y"),PRODUCT(G$6, Prices!$D17),0)) -> 0 | H31: =IF(OR(Inputs!H$4="Y", H$6 = 0), 0, IF(OR(Inputs!H16="Y",Inputs!H$20="Y"),PRODUCT(H$6, Prices!$D17),0)) -> 0
C32: PRM Medicare ACO Analytics (CCLF Only) | D32: 0 | E32: 0 | F32: 0 | G32: 0 | H32: 0
B34: Annual Base Data Fees (Actual, with knockouts):
C35: Base Processing Fee | D35: =IF(Inputs!D4="Y", Prices!$C$6, IF(Inputs!D4="N", Prices!$D$6, 0)) -> 15000 | E35: =IF(Inputs!E4="Y", Prices!$C$6, IF(Inputs!E4="N", Prices!$D$6, 0)) -> 0 | F35: =IF(Inputs!F4="Y", Prices!$C$6, IF(Inputs!F4="N", Prices!$D$6, 0)) -> 0 | G35: =IF(Inputs!G4="Y", Prices!$C$6, IF(Inputs!G4="N", Prices!$D$6, 0)) -> 0 | H35: =IF(Inputs!H4="Y", Prices!$C$6, IF(Inputs!H4="N", Prices!$D$6, 0)) -> 0
C36: Datamart Fee | D36: =IF(Inputs!D8="Y", Prices!$C$7, 0) -> 6750 | E36: =IF(Inputs!E8="Y", Prices!$C$7, 0) -> 0 | F36: =IF(Inputs!F8="Y", Prices!$C$7, 0) -> 0 | G36: =IF(Inputs!G8="Y", Prices!$C$7, 0) -> 0 | H36: =IF(Inputs!H8="Y", Prices!$C$7, 0) -> 0
C37: HCC Risk Scores | D37: =IF(AND(Inputs!D9="Y",Inputs!D$19="N"),Prices!$C10,0) -> 0 | E37: =IF(AND(Inputs!E9="Y",Inputs!E$19="N"),Prices!$C10,0) -> 0 | F37: =IF(AND(Inputs!F9="Y",Inputs!F$19="N"),Prices!$C10,0) -> 0 | G37: =IF(AND(Inputs!G9="Y",Inputs!G$19="N"),Prices!$C10,0) -> 0 | H37: =IF(AND(Inputs!H9="Y",Inputs!H$19="N"),Prices!$C10,0) -> 0
C38: HCG Benchmarks | D38: =IF(AND(Inputs!D10="Y",Inputs!D$19="N"),Prices!$C11,0) -> 0 | E38: =IF(AND(Inputs!E10="Y",Inputs!E$19="N"),Prices!$C11,0) -> 0 | F38: =IF(AND(Inputs!F10="Y",Inputs!F$19="N"),Prices!$C11,0) -> 0 | G38: =IF(AND(Inputs!G10="Y",Inputs!G$19="N"),Prices!$C11,0) -> 0 | H38: =IF(AND(Inputs!H10="Y",Inputs!H$19="N"),Prices!$C11,0) -> 0
C39: PAC/Grouping/Benchmarks | D39: =IF(AND(Inputs!D11="Y",Inputs!D$19="N"),Prices!$C12,0) -> 0 | E39: =IF(AND(Inputs!E11="Y",Inputs!E$19="N"),Prices!$C12,0) -> 0 | F39: =IF(AND(Inputs!F11="Y",Inputs!F$19="N"),Prices!$C12,0) -> 0 | G39: =IF(AND(Inputs!G11="Y",Inputs!G$19="N"),Prices!$C12,0) -> 0 | H39: =IF(AND(Inputs!H11="Y",Inputs!H$19="N"),Prices!$C12,0) -> 0
C40: Key Claims Metrics | D40: =IF(AND(Inputs!D12="Y",Inputs!D$19="N"),Prices!$C13,0) -> 0 | E40: =IF(AND(Inputs!E12="Y",Inputs!E$19="N"),Prices!$C13,0) -> 0 | F40: =IF(AND(Inputs!F12="Y",Inputs!F$19="N"),Prices!$C13,0) -> 0 | G40: =IF(AND(Inputs!G12="Y",Inputs!G$19="N"),Prices!$C13,0) -> 0 | H40: =IF(AND(Inputs!H12="Y",Inputs!H$19="N"),Prices!$C13,0) -> 0
C41: Waste Calculator | D41: =IF(AND(Inputs!D13="Y",Inputs!D$19="N"),Prices!$C14,0) -> 0 | E41: =IF(AND(Inputs!E13="Y",Inputs!E$19="N"),Prices!$C14,0) -> 0 | F41: =IF(AND(Inputs!F13="Y",Inputs!F$19="N"),Prices!$C14,0) -> 0 | G41: =IF(AND(Inputs!G13="Y",Inputs!G$19="N"),Prices!$C14,0) -> 0 | H41: =IF(AND(Inputs!H13="Y",Inputs!H$19="N"),Prices!$C14,0) -> 0
C42: Medical Conditions | D42: =IF(AND(Inputs!D14="Y",Inputs!D$19="N"),Prices!$C15,0) -> 0 | E42: =IF(AND(Inputs!E14="Y",Inputs!E$19="N"),Prices!$C15,0) -> 0 | F42: =IF(AND(Inputs!F14="Y",Inputs!F$19="N"),Prices!$C15,0) -> 0 | G42: =IF(AND(Inputs!G14="Y",Inputs!G$19="N"),Prices!$C15,0) -> 0 | H42: =IF(AND(Inputs!H14="Y",Inputs!H$19="N"),Prices!$C15,0) -> 0
C43: PRM Oppourtunity Prospective Scores | D43: =IF(AND(Inputs!D15="Y",Inputs!D$20="N"),Prices!$C16,0) -> 0 | E43: =IF(AND(Inputs!E15="Y",Inputs!E$20="N"),Prices!$C16,0) -> 0 | F43: =IF(AND(Inputs!F15="Y",Inputs!F$20="N"),Prices!$C16,0) -> 0 | G43: =IF(AND(Inputs!G15="Y",Inputs!G$20="N"),Prices!$C16,0) -> 0 | H43: =IF(AND(Inputs!H15="Y",Inputs!H$20="N"),Prices!$C16,0) -> 0
C44: PRM Conditions to Consider | D44: =IF(AND(Inputs!D16="Y",Inputs!D$20="N"),Prices!$C17,0) -> 0 | E44: =IF(AND(Inputs!E16="Y",Inputs!E$20="N"),Prices!$C17,0) -> 0 | F44: =IF(AND(Inputs!F16="Y",Inputs!F$20="N"),Prices!$C17,0) -> 0 | G44: =IF(AND(Inputs!G16="Y",Inputs!G$20="N"),Prices!$C17,0) -> 0 | H44: =IF(AND(Inputs!H16="Y",Inputs!H$20="N"),Prices!$C17,0) -> 0
C45: PRM Medicare ACO Analytics (CCLF Only) | D45: =IF(AND(Inputs!D17="Y",Inputs!D$20="N"),Prices!$C18,0) -> 0 | E45: =IF(AND(Inputs!E17="Y",Inputs!E$20="N"),Prices!$C18,0) -> 0 | F45: =IF(AND(Inputs!F17="Y",Inputs!F$20="N"),Prices!$C18,0) -> 0 | G45: =IF(AND(Inputs!G17="Y",Inputs!G$20="N"),Prices!$C18,0) -> 0 | H45: =IF(AND(Inputs!H17="Y",Inputs!H$20="N"),Prices!$C18,0) -> 0
...

Sheet Prices
C2: CCLF | D2: Non-CCLF
B3: Implementation Fees | C3: 5000 | D3: 32750 | H3: Multi-Product Discounts
B4: Implementation Add-On (non-CMS Files) | C4: 5000 | D4: 0 | H4: Most Expensive Product | I4: 0
E5: PMPY Add-On | H5: 2nd Most Expensive Product | I5: 0.3
B6: Base Processing Fees | C6: 15000 | D6: 30000 | E6: 0.27 | H6: 3rd Most Expensive Product | I6: 0.45
B7: Basic Data Mart Fees | C7: 6750 | D7: 6750 | E7: 0
H8: Multi-Datafeed Discounts
C9: Base | D9: PMPY Add-On | H9: Most Expensive Datafeed | I9: 0
B10: HCC Risk Scores | C10: 1000 | D10: 0.04 | H10: 2nd Most Expensive Datafeed | I10: 0.45
B11: HCG Benchmarks | C11: 4000 | D11: 0.05 | H11: 3rd Most Expensive Datafeed | I11: 0.5
B12: PAC/Grouping/Benchmarks | C12: 2000 | D12: 0.04
B13: Key Claims Metrics | C13: 2000 | D13: 0.04
B14: Waste Calculator | C14: 6000 | D14: 0.05 | H14: Annual Increase | I14: 0.0125
B15: Medical Conditions | C15: 4000 | D15: 0.05 | H15: First Annual Increase | I15: 43466
B16: PRM Oppourtunity Prospective Scores | C16: 10000 | D16: 0.18
B17: PRM Conditions to Consider | C17: 5000 | D17: 0.07 | H17: Exisitng Collaborative Member Discount | I17: 0.15
B18: PRM Medicare ACO Analytics (CCLF Only) | C18: 5000 | D18: 0 | H18: Expires | I18: 44197
B20: ACO Insight - Basic | C20: 8500 | D20: 0
B21: ACO Insight - Enhanced | C21: 33000 | D21: 0.28
B22: PRM Care Coordinator Report | C22: 35000 | D22: 0.29
B23: PRM Physician Risk and Credibility Adjusted Report | C23: 28000 | D23: 0.18
